[Thu May 05 14:54:35.022391 2016] [authz_core:error] [pid 23401:tid 140115532457728] [client 127.0.0.1:47368] AH01630: client denied by server configuration: /home/lpa/atinfo/web/at-info/web/
[Thu May 05 14:54:35.189594 2016] [authz_core:error] [pid 23401:tid 140115540850432] [client 127.0.0.1:47368] AH01630: client denied by server configuration: /home/lpa/atinfo/web/at-info/web/favicon.ico
[Thu May 05 14:54:35.315757 2016] [authz_core:error] [pid 23401:tid 140115549243136] [client 127.0.0.1:47368] AH01630: client denied by server configuration: /home/lpa/atinfo/web/at-info/web/favicon.ico
[Thu May 05 14:56:36.749857 2016] [authz_core:error] [pid 23608:tid 140115313616640] [client 127.0.0.1:47372] AH01630: client denied by server configuration: /home/lpa/atinfo/www/at-info/web/
[Thu May 05 14:56:37.782343 2016] [authz_core:error] [pid 23608:tid 140115305223936] [client 127.0.0.1:47372] AH01630: client denied by server configuration: /home/lpa/atinfo/www/at-info/web/
[Thu May 05 14:56:38.493991 2016] [authz_core:error] [pid 23608:tid 140115296831232] [client 127.0.0.1:47372] AH01630: client denied by server configuration: /home/lpa/atinfo/www/at-info/web/
[Thu May 05 14:56:38.956890 2016] [authz_core:error] [pid 23608:tid 140115322009344] [client 127.0.0.1:47372] AH01630: client denied by server configuration: /home/lpa/atinfo/www/at-info/web/
[Thu May 05 14:56:39.741552 2016] [authz_core:error] [pid 23608:tid 140115566028544] [client 127.0.0.1:47372] AH01630: client denied by server configuration: /home/lpa/atinfo/www/at-info/web/
[Sun May 22 13:02:42.446975 2016] [:error] [pid 3336] [client 127.0.0.1:46346] PHP Parse error:  syntax error, unexpected 'use' (T_USE), expecting ',' or ';' in /home/lpa/atinfo/www/at-info/src/controllers.php on line 7
[Sun May 22 13:02:44.839816 2016] [:error] [pid 3338] [client 127.0.0.1:46348] PHP Parse error:  syntax error, unexpected 'use' (T_USE), expecting ',' or ';' in /home/lpa/atinfo/www/at-info/src/controllers.php on line 7
[Sun May 22 13:02:45.020568 2016] [:error] [pid 3330] [client 127.0.0.1:46350] PHP Parse error:  syntax error, unexpected 'use' (T_USE), expecting ',' or ';' in /home/lpa/atinfo/www/at-info/src/controllers.php on line 7
[Sun May 22 13:02:45.157238 2016] [:error] [pid 1181] [client 127.0.0.1:46352] PHP Parse error:  syntax error, unexpected 'use' (T_USE), expecting ',' or ';' in /home/lpa/atinfo/www/at-info/src/controllers.php on line 7
[Sun May 22 17:12:07.289038 2016] [:error] [pid 5579] [client 127.0.0.1:49320] PHP Fatal error:  Uncaught TypeError: Argument 1 passed to Symfony\\Component\\Debug\\ExceptionHandler::handle() must be an instance of Exception, instance of Error given in /home/lpa/atinfo/www/at-info/vendor/symfony/debug/Symfony/Component/Debug/ExceptionHandler.php:90\nStack trace:\n#0 [internal function]: Symfony\\Component\\Debug\\ExceptionHandler->handle(Object(Error))\n#1 {main}\n  thrown in /home/lpa/atinfo/www/at-info/vendor/symfony/debug/Symfony/Component/Debug/ExceptionHandler.php on line 90, referer: http://at-info/services
[Sun May 22 17:12:32.720299 2016] [:error] [pid 5737] [client 127.0.0.1:49322] PHP Fatal error:  Uncaught TypeError: Argument 1 passed to Symfony\\Component\\Debug\\ExceptionHandler::handle() must be an instance of Exception, instance of Error given in /home/lpa/atinfo/www/at-info/vendor/symfony/debug/Symfony/Component/Debug/ExceptionHandler.php:90\nStack trace:\n#0 [internal function]: Symfony\\Component\\Debug\\ExceptionHandler->handle(Object(Error))\n#1 {main}\n  thrown in /home/lpa/atinfo/www/at-info/vendor/symfony/debug/Symfony/Component/Debug/ExceptionHandler.php on line 90
[Sun May 22 17:13:35.452549 2016] [:error] [pid 5738] [client 127.0.0.1:49328] PHP Fatal error:  Uncaught TypeError: Argument 1 passed to Symfony\\Component\\Debug\\ExceptionHandler::handle() must be an instance of Exception, instance of Error given in /home/lpa/atinfo/www/at-info/vendor/symfony/debug/Symfony/Component/Debug/ExceptionHandler.php:90\nStack trace:\n#0 [internal function]: Symfony\\Component\\Debug\\ExceptionHandler->handle(Object(Error))\n#1 {main}\n  thrown in /home/lpa/atinfo/www/at-info/vendor/symfony/debug/Symfony/Component/Debug/ExceptionHandler.php on line 90
[Sun May 22 17:17:14.020689 2016] [:error] [pid 5586] [client 127.0.0.1:49432] PHP Fatal error:  Uncaught TypeError: Argument 1 passed to Symfony\\Component\\Debug\\ExceptionHandler::handle() must be an instance of Exception, instance of Error given in /home/lpa/atinfo/www/at-info/vendor/symfony/debug/Symfony/Component/Debug/ExceptionHandler.php:90\nStack trace:\n#0 [internal function]: Symfony\\Component\\Debug\\ExceptionHandler->handle(Object(Error))\n#1 {main}\n  thrown in /home/lpa/atinfo/www/at-info/vendor/symfony/debug/Symfony/Component/Debug/ExceptionHandler.php on line 90
[Sun May 22 17:20:24.733985 2016] [:error] [pid 6751] [client 127.0.0.1:49476] PHP Fatal error:  Uncaught TypeError: Argument 1 passed to Symfony\\Component\\Debug\\ExceptionHandler::handle() must be an instance of Exception, instance of Error given in /home/lpa/atinfo/www/at-info/vendor/symfony/debug/Symfony/Component/Debug/ExceptionHandler.php:90\nStack trace:\n#0 [internal function]: Symfony\\Component\\Debug\\ExceptionHandler->handle(Object(Error))\n#1 {main}\n  thrown in /home/lpa/atinfo/www/at-info/vendor/symfony/debug/Symfony/Component/Debug/ExceptionHandler.php on line 90
[Sun May 22 17:20:25.502368 2016] [:error] [pid 5583] [client 127.0.0.1:49478] PHP Fatal error:  Uncaught TypeError: Argument 1 passed to Symfony\\Component\\Debug\\ExceptionHandler::handle() must be an instance of Exception, instance of Error given in /home/lpa/atinfo/www/at-info/vendor/symfony/debug/Symfony/Component/Debug/ExceptionHandler.php:90\nStack trace:\n#0 [internal function]: Symfony\\Component\\Debug\\ExceptionHandler->handle(Object(Error))\n#1 {main}\n  thrown in /home/lpa/atinfo/www/at-info/vendor/symfony/debug/Symfony/Component/Debug/ExceptionHandler.php on line 90
[Sun May 22 17:20:25.980561 2016] [:error] [pid 5581] [client 127.0.0.1:49480] PHP Fatal error:  Uncaught TypeError: Argument 1 passed to Symfony\\Component\\Debug\\ExceptionHandler::handle() must be an instance of Exception, instance of Error given in /home/lpa/atinfo/www/at-info/vendor/symfony/debug/Symfony/Component/Debug/ExceptionHandler.php:90\nStack trace:\n#0 [internal function]: Symfony\\Component\\Debug\\ExceptionHandler->handle(Object(Error))\n#1 {main}\n  thrown in /home/lpa/atinfo/www/at-info/vendor/symfony/debug/Symfony/Component/Debug/ExceptionHandler.php on line 90
[Sun May 22 17:25:24.225514 2016] [:error] [pid 5737] [client 127.0.0.1:49692] PHP Fatal error:  Uncaught TypeError: Argument 1 passed to Symfony\\Component\\Debug\\ExceptionHandler::handle() must be an instance of Exception, instance of Error given in /home/lpa/atinfo/www/at-info/vendor/symfony/debug/Symfony/Component/Debug/ExceptionHandler.php:90\nStack trace:\n#0 [internal function]: Symfony\\Component\\Debug\\ExceptionHandler->handle(Object(Error))\n#1 {main}\n  thrown in /home/lpa/atinfo/www/at-info/vendor/symfony/debug/Symfony/Component/Debug/ExceptionHandler.php on line 90
[Sun May 22 17:26:30.391417 2016] [:error] [pid 5738] [client 127.0.0.1:49700] PHP Fatal error:  Uncaught TypeError: Argument 1 passed to Symfony\\Component\\Debug\\ExceptionHandler::handle() must be an instance of Exception, instance of Error given in /home/lpa/atinfo/www/at-info/vendor/symfony/debug/Symfony/Component/Debug/ExceptionHandler.php:90\nStack trace:\n#0 [internal function]: Symfony\\Component\\Debug\\ExceptionHandler->handle(Object(Error))\n#1 {main}\n  thrown in /home/lpa/atinfo/www/at-info/vendor/symfony/debug/Symfony/Component/Debug/ExceptionHandler.php on line 90
[Sun May 22 17:27:35.080177 2016] [:error] [pid 5737] [client 127.0.0.1:49722] PHP Fatal error:  Uncaught TypeError: Argument 1 passed to Symfony\\Component\\Debug\\ExceptionHandler::handle() must be an instance of Exception, instance of Error given in /home/lpa/atinfo/www/at-info/vendor/symfony/debug/Symfony/Component/Debug/ExceptionHandler.php:90\nStack trace:\n#0 [internal function]: Symfony\\Component\\Debug\\ExceptionHandler->handle(Object(Error))\n#1 {main}\n  thrown in /home/lpa/atinfo/www/at-info/vendor/symfony/debug/Symfony/Component/Debug/ExceptionHandler.php on line 90
[Sun May 22 17:27:40.506546 2016] [:error] [pid 5738] [client 127.0.0.1:49728] PHP Fatal error:  Uncaught TypeError: Argument 1 passed to Symfony\\Component\\Debug\\ExceptionHandler::handle() must be an instance of Exception, instance of Error given in /home/lpa/atinfo/www/at-info/vendor/symfony/debug/Symfony/Component/Debug/ExceptionHandler.php:90\nStack trace:\n#0 [internal function]: Symfony\\Component\\Debug\\ExceptionHandler->handle(Object(Error))\n#1 {main}\n  thrown in /home/lpa/atinfo/www/at-info/vendor/symfony/debug/Symfony/Component/Debug/ExceptionHandler.php on line 90
[Sun May 22 17:27:43.246929 2016] [:error] [pid 5580] [client 127.0.0.1:49730] PHP Fatal error:  Uncaught TypeError: Argument 1 passed to Symfony\\Component\\Debug\\ExceptionHandler::handle() must be an instance of Exception, instance of Error given in /home/lpa/atinfo/www/at-info/vendor/symfony/debug/Symfony/Component/Debug/ExceptionHandler.php:90\nStack trace:\n#0 [internal function]: Symfony\\Component\\Debug\\ExceptionHandler->handle(Object(Error))\n#1 {main}\n  thrown in /home/lpa/atinfo/www/at-info/vendor/symfony/debug/Symfony/Component/Debug/ExceptionHandler.php on line 90
[Sun May 22 17:28:58.336989 2016] [:error] [pid 6751] [client 127.0.0.1:49734] PHP Fatal error:  Uncaught TypeError: Argument 1 passed to Symfony\\Component\\Debug\\ExceptionHandler::handle() must be an instance of Exception, instance of Error given in /home/lpa/atinfo/www/at-info/vendor/symfony/debug/Symfony/Component/Debug/ExceptionHandler.php:90\nStack trace:\n#0 [internal function]: Symfony\\Component\\Debug\\ExceptionHandler->handle(Object(Error))\n#1 {main}\n  thrown in /home/lpa/atinfo/www/at-info/vendor/symfony/debug/Symfony/Component/Debug/ExceptionHandler.php on line 90
[Sun May 22 17:28:59.341304 2016] [:error] [pid 5583] [client 127.0.0.1:49736] PHP Fatal error:  Uncaught TypeError: Argument 1 passed to Symfony\\Component\\Debug\\ExceptionHandler::handle() must be an instance of Exception, instance of Error given in /home/lpa/atinfo/www/at-info/vendor/symfony/debug/Symfony/Component/Debug/ExceptionHandler.php:90\nStack trace:\n#0 [internal function]: Symfony\\Component\\Debug\\ExceptionHandler->handle(Object(Error))\n#1 {main}\n  thrown in /home/lpa/atinfo/www/at-info/vendor/symfony/debug/Symfony/Component/Debug/ExceptionHandler.php on line 90
[Sun May 22 17:29:19.015289 2016] [:error] [pid 5737] [client 127.0.0.1:49746] PHP Fatal error:  Uncaught TypeError: Argument 1 passed to Symfony\\Component\\Debug\\ExceptionHandler::handle() must be an instance of Exception, instance of Error given in /home/lpa/atinfo/www/at-info/vendor/symfony/debug/Symfony/Component/Debug/ExceptionHandler.php:90\nStack trace:\n#0 [internal function]: Symfony\\Component\\Debug\\ExceptionHandler->handle(Object(Error))\n#1 {main}\n  thrown in /home/lpa/atinfo/www/at-info/vendor/symfony/debug/Symfony/Component/Debug/ExceptionHandler.php on line 90
[Sun May 22 17:30:17.946326 2016] [:error] [pid 5580] [client 127.0.0.1:49752] PHP Fatal error:  Uncaught TypeError: Argument 1 passed to Symfony\\Component\\Debug\\ExceptionHandler::handle() must be an instance of Exception, instance of Error given in /home/lpa/atinfo/www/at-info/vendor/symfony/debug/Symfony/Component/Debug/ExceptionHandler.php:90\nStack trace:\n#0 [internal function]: Symfony\\Component\\Debug\\ExceptionHandler->handle(Object(Error))\n#1 {main}\n  thrown in /home/lpa/atinfo/www/at-info/vendor/symfony/debug/Symfony/Component/Debug/ExceptionHandler.php on line 90
[Sun May 22 17:32:45.265715 2016] [:error] [pid 5737] [client 127.0.0.1:49770] PHP Fatal error:  Uncaught TypeError: Argument 1 passed to Symfony\\Component\\Debug\\ExceptionHandler::handle() must be an instance of Exception, instance of Error given in /home/lpa/atinfo/www/at-info/vendor/symfony/debug/Symfony/Component/Debug/ExceptionHandler.php:90\nStack trace:\n#0 [internal function]: Symfony\\Component\\Debug\\ExceptionHandler->handle(Object(Error))\n#1 {main}\n  thrown in /home/lpa/atinfo/www/at-info/vendor/symfony/debug/Symfony/Component/Debug/ExceptionHandler.php on line 90
[Sun May 22 17:33:41.856596 2016] [:error] [pid 5738] [client 127.0.0.1:49776] PHP Fatal error:  Uncaught TypeError: Argument 1 passed to Symfony\\Component\\Debug\\ExceptionHandler::handle() must be an instance of Exception, instance of Error given in /home/lpa/atinfo/www/at-info/vendor/symfony/debug/Symfony/Component/Debug/ExceptionHandler.php:90\nStack trace:\n#0 [internal function]: Symfony\\Component\\Debug\\ExceptionHandler->handle(Object(Error))\n#1 {main}\n  thrown in /home/lpa/atinfo/www/at-info/vendor/symfony/debug/Symfony/Component/Debug/ExceptionHandler.php on line 90
[Sun May 22 17:33:42.760759 2016] [:error] [pid 5580] [client 127.0.0.1:49778] PHP Fatal error:  Uncaught TypeError: Argument 1 passed to Symfony\\Component\\Debug\\ExceptionHandler::handle() must be an instance of Exception, instance of Error given in /home/lpa/atinfo/www/at-info/vendor/symfony/debug/Symfony/Component/Debug/ExceptionHandler.php:90\nStack trace:\n#0 [internal function]: Symfony\\Component\\Debug\\ExceptionHandler->handle(Object(Error))\n#1 {main}\n  thrown in /home/lpa/atinfo/www/at-info/vendor/symfony/debug/Symfony/Component/Debug/ExceptionHandler.php on line 90
[Sun May 22 17:33:42.993754 2016] [:error] [pid 5586] [client 127.0.0.1:49780] PHP Fatal error:  Uncaught TypeError: Argument 1 passed to Symfony\\Component\\Debug\\ExceptionHandler::handle() must be an instance of Exception, instance of Error given in /home/lpa/atinfo/www/at-info/vendor/symfony/debug/Symfony/Component/Debug/ExceptionHandler.php:90\nStack trace:\n#0 [internal function]: Symfony\\Component\\Debug\\ExceptionHandler->handle(Object(Error))\n#1 {main}\n  thrown in /home/lpa/atinfo/www/at-info/vendor/symfony/debug/Symfony/Component/Debug/ExceptionHandler.php on line 90
[Sun May 22 17:33:43.131308 2016] [:error] [pid 6751] [client 127.0.0.1:49782] PHP Fatal error:  Uncaught TypeError: Argument 1 passed to Symfony\\Component\\Debug\\ExceptionHandler::handle() must be an instance of Exception, instance of Error given in /home/lpa/atinfo/www/at-info/vendor/symfony/debug/Symfony/Component/Debug/ExceptionHandler.php:90\nStack trace:\n#0 [internal function]: Symfony\\Component\\Debug\\ExceptionHandler->handle(Object(Error))\n#1 {main}\n  thrown in /home/lpa/atinfo/www/at-info/vendor/symfony/debug/Symfony/Component/Debug/ExceptionHandler.php on line 90
[Sun May 22 17:38:46.645770 2016] [:error] [pid 5586] [client 127.0.0.1:49828] PHP Fatal error:  Uncaught TypeError: Argument 1 passed to Symfony\\Component\\Debug\\ExceptionHandler::handle() must be an instance of Exception, instance of Error given in /home/lpa/atinfo/www/at-info/vendor/symfony/debug/Symfony/Component/Debug/ExceptionHandler.php:90\nStack trace:\n#0 [internal function]: Symfony\\Component\\Debug\\ExceptionHandler->handle(Object(Error))\n#1 {main}\n  thrown in /home/lpa/atinfo/www/at-info/vendor/symfony/debug/Symfony/Component/Debug/ExceptionHandler.php on line 90
[Sun May 22 17:38:47.575518 2016] [:error] [pid 5583] [client 127.0.0.1:49830] PHP Fatal error:  Uncaught TypeError: Argument 1 passed to Symfony\\Component\\Debug\\ExceptionHandler::handle() must be an instance of Exception, instance of Error given in /home/lpa/atinfo/www/at-info/vendor/symfony/debug/Symfony/Component/Debug/ExceptionHandler.php:90\nStack trace:\n#0 [internal function]: Symfony\\Component\\Debug\\ExceptionHandler->handle(Object(Error))\n#1 {main}\n  thrown in /home/lpa/atinfo/www/at-info/vendor/symfony/debug/Symfony/Component/Debug/ExceptionHandler.php on line 90
[Sun May 22 17:43:59.362866 2016] [:error] [pid 5583] [client 127.0.0.1:49992] PHP Fatal error:  Uncaught TypeError: Argument 1 passed to Symfony\\Component\\Debug\\ExceptionHandler::handle() must be an instance of Exception, instance of Error given in /home/lpa/atinfo/www/at-info/vendor/symfony/debug/Symfony/Component/Debug/ExceptionHandler.php:90\nStack trace:\n#0 [internal function]: Symfony\\Component\\Debug\\ExceptionHandler->handle(Object(Error))\n#1 {main}\n  thrown in /home/lpa/atinfo/www/at-info/vendor/symfony/debug/Symfony/Component/Debug/ExceptionHandler.php on line 90
[Sun May 22 17:44:00.477408 2016] [:error] [pid 5586] [client 127.0.0.1:49994] PHP Fatal error:  Uncaught TypeError: Argument 1 passed to Symfony\\Component\\Debug\\ExceptionHandler::handle() must be an instance of Exception, instance of Error given in /home/lpa/atinfo/www/at-info/vendor/symfony/debug/Symfony/Component/Debug/ExceptionHandler.php:90\nStack trace:\n#0 [internal function]: Symfony\\Component\\Debug\\ExceptionHandler->handle(Object(Error))\n#1 {main}\n  thrown in /home/lpa/atinfo/www/at-info/vendor/symfony/debug/Symfony/Component/Debug/ExceptionHandler.php on line 90
[Sun May 22 17:44:00.643222 2016] [:error] [pid 5738] [client 127.0.0.1:49998] PHP Fatal error:  Uncaught TypeError: Argument 1 passed to Symfony\\Component\\Debug\\ExceptionHandler::handle() must be an instance of Exception, instance of Error given in /home/lpa/atinfo/www/at-info/vendor/symfony/debug/Symfony/Component/Debug/ExceptionHandler.php:90\nStack trace:\n#0 [internal function]: Symfony\\Component\\Debug\\ExceptionHandler->handle(Object(Error))\n#1 {main}\n  thrown in /home/lpa/atinfo/www/at-info/vendor/symfony/debug/Symfony/Component/Debug/ExceptionHandler.php on line 90
[Sun May 22 17:44:00.851569 2016] [:error] [pid 5739] [client 127.0.0.1:50000] PHP Fatal error:  Uncaught TypeError: Argument 1 passed to Symfony\\Component\\Debug\\ExceptionHandler::handle() must be an instance of Exception, instance of Error given in /home/lpa/atinfo/www/at-info/vendor/symfony/debug/Symfony/Component/Debug/ExceptionHandler.php:90\nStack trace:\n#0 [internal function]: Symfony\\Component\\Debug\\ExceptionHandler->handle(Object(Error))\n#1 {main}\n  thrown in /home/lpa/atinfo/www/at-info/vendor/symfony/debug/Symfony/Component/Debug/ExceptionHandler.php on line 90
[Sun May 22 17:44:00.926783 2016] [:error] [pid 6751] [client 127.0.0.1:50002] PHP Fatal error:  Uncaught TypeError: Argument 1 passed to Symfony\\Component\\Debug\\ExceptionHandler::handle() must be an instance of Exception, instance of Error given in /home/lpa/atinfo/www/at-info/vendor/symfony/debug/Symfony/Component/Debug/ExceptionHandler.php:90\nStack trace:\n#0 [internal function]: Symfony\\Component\\Debug\\ExceptionHandler->handle(Object(Error))\n#1 {main}\n  thrown in /home/lpa/atinfo/www/at-info/vendor/symfony/debug/Symfony/Component/Debug/ExceptionHandler.php on line 90
[Sun May 22 17:44:01.123828 2016] [:error] [pid 5582] [client 127.0.0.1:50004] PHP Fatal error:  Uncaught TypeError: Argument 1 passed to Symfony\\Component\\Debug\\ExceptionHandler::handle() must be an instance of Exception, instance of Error given in /home/lpa/atinfo/www/at-info/vendor/symfony/debug/Symfony/Component/Debug/ExceptionHandler.php:90\nStack trace:\n#0 [internal function]: Symfony\\Component\\Debug\\ExceptionHandler->handle(Object(Error))\n#1 {main}\n  thrown in /home/lpa/atinfo/www/at-info/vendor/symfony/debug/Symfony/Component/Debug/ExceptionHandler.php on line 90
[Sun May 22 17:44:01.279782 2016] [:error] [pid 5581] [client 127.0.0.1:50006] PHP Fatal error:  Uncaught TypeError: Argument 1 passed to Symfony\\Component\\Debug\\ExceptionHandler::handle() must be an instance of Exception, instance of Error given in /home/lpa/atinfo/www/at-info/vendor/symfony/debug/Symfony/Component/Debug/ExceptionHandler.php:90\nStack trace:\n#0 [internal function]: Symfony\\Component\\Debug\\ExceptionHandler->handle(Object(Error))\n#1 {main}\n  thrown in /home/lpa/atinfo/www/at-info/vendor/symfony/debug/Symfony/Component/Debug/ExceptionHandler.php on line 90
[Sun May 22 17:44:43.357875 2016] [:error] [pid 5739] [client 127.0.0.1:50044] PHP Fatal error:  Uncaught TypeError: Argument 1 passed to Symfony\\Component\\Debug\\ExceptionHandler::handle() must be an instance of Exception, instance of Error given in /home/lpa/atinfo/www/at-info/vendor/symfony/debug/Symfony/Component/Debug/ExceptionHandler.php:90\nStack trace:\n#0 [internal function]: Symfony\\Component\\Debug\\ExceptionHandler->handle(Object(Error))\n#1 {main}\n  thrown in /home/lpa/atinfo/www/at-info/vendor/symfony/debug/Symfony/Component/Debug/ExceptionHandler.php on line 90
[Sun May 22 17:44:44.241609 2016] [:error] [pid 5581] [client 127.0.0.1:50046] PHP Fatal error:  Uncaught TypeError: Argument 1 passed to Symfony\\Component\\Debug\\ExceptionHandler::handle() must be an instance of Exception, instance of Error given in /home/lpa/atinfo/www/at-info/vendor/symfony/debug/Symfony/Component/Debug/ExceptionHandler.php:90\nStack trace:\n#0 [internal function]: Symfony\\Component\\Debug\\ExceptionHandler->handle(Object(Error))\n#1 {main}\n  thrown in /home/lpa/atinfo/www/at-info/vendor/symfony/debug/Symfony/Component/Debug/ExceptionHandler.php on line 90
[Sun May 22 17:45:09.627978 2016] [:error] [pid 5580] [client 127.0.0.1:50070] PHP Fatal error:  Uncaught TypeError: Argument 1 passed to Symfony\\Component\\Debug\\ExceptionHandler::handle() must be an instance of Exception, instance of Error given in /home/lpa/atinfo/www/at-info/vendor/symfony/debug/Symfony/Component/Debug/ExceptionHandler.php:90\nStack trace:\n#0 [internal function]: Symfony\\Component\\Debug\\ExceptionHandler->handle(Object(Error))\n#1 {main}\n  thrown in /home/lpa/atinfo/www/at-info/vendor/symfony/debug/Symfony/Component/Debug/ExceptionHandler.php on line 90
[Sun May 22 17:45:10.524718 2016] [:error] [pid 5737] [client 127.0.0.1:50074] PHP Fatal error:  Uncaught TypeError: Argument 1 passed to Symfony\\Component\\Debug\\ExceptionHandler::handle() must be an instance of Exception, instance of Error given in /home/lpa/atinfo/www/at-info/vendor/symfony/debug/Symfony/Component/Debug/ExceptionHandler.php:90\nStack trace:\n#0 [internal function]: Symfony\\Component\\Debug\\ExceptionHandler->handle(Object(Error))\n#1 {main}\n  thrown in /home/lpa/atinfo/www/at-info/vendor/symfony/debug/Symfony/Component/Debug/ExceptionHandler.php on line 90
[Sun May 22 17:49:28.692326 2016] [:error] [pid 5581] [client 127.0.0.1:50238] PHP Fatal error:  Uncaught TypeError: Argument 1 passed to Symfony\\Component\\Debug\\ExceptionHandler::handle() must be an instance of Exception, instance of Error given in /home/lpa/atinfo/www/at-info/vendor/symfony/debug/Symfony/Component/Debug/ExceptionHandler.php:90\nStack trace:\n#0 [internal function]: Symfony\\Component\\Debug\\ExceptionHandler->handle(Object(Error))\n#1 {main}\n  thrown in /home/lpa/atinfo/www/at-info/vendor/symfony/debug/Symfony/Component/Debug/ExceptionHandler.php on line 90
[Sun May 22 17:49:30.041225 2016] [:error] [pid 6751] [client 127.0.0.1:50240] PHP Fatal error:  Uncaught TypeError: Argument 1 passed to Symfony\\Component\\Debug\\ExceptionHandler::handle() must be an instance of Exception, instance of Error given in /home/lpa/atinfo/www/at-info/vendor/symfony/debug/Symfony/Component/Debug/ExceptionHandler.php:90\nStack trace:\n#0 [internal function]: Symfony\\Component\\Debug\\ExceptionHandler->handle(Object(Error))\n#1 {main}\n  thrown in /home/lpa/atinfo/www/at-info/vendor/symfony/debug/Symfony/Component/Debug/ExceptionHandler.php on line 90
[Sun May 22 17:49:31.309137 2016] [:error] [pid 5739] [client 127.0.0.1:50244] PHP Fatal error:  Uncaught TypeError: Argument 1 passed to Symfony\\Component\\Debug\\ExceptionHandler::handle() must be an instance of Exception, instance of Error given in /home/lpa/atinfo/www/at-info/vendor/symfony/debug/Symfony/Component/Debug/ExceptionHandler.php:90\nStack trace:\n#0 [internal function]: Symfony\\Component\\Debug\\ExceptionHandler->handle(Object(Error))\n#1 {main}\n  thrown in /home/lpa/atinfo/www/at-info/vendor/symfony/debug/Symfony/Component/Debug/ExceptionHandler.php on line 90
[Sun May 22 17:49:33.714473 2016] [:error] [pid 5738] [client 127.0.0.1:50246] PHP Fatal error:  Uncaught TypeError: Argument 1 passed to Symfony\\Component\\Debug\\ExceptionHandler::handle() must be an instance of Exception, instance of Error given in /home/lpa/atinfo/www/at-info/vendor/symfony/debug/Symfony/Component/Debug/ExceptionHandler.php:90\nStack trace:\n#0 [internal function]: Symfony\\Component\\Debug\\ExceptionHandler->handle(Object(Error))\n#1 {main}\n  thrown in /home/lpa/atinfo/www/at-info/vendor/symfony/debug/Symfony/Component/Debug/ExceptionHandler.php on line 90
[Sun May 22 17:52:28.953887 2016] [:error] [pid 5586] [client 127.0.0.1:50254] PHP Fatal error:  Uncaught TypeError: Argument 1 passed to Symfony\\Component\\Debug\\ExceptionHandler::handle() must be an instance of Exception, instance of Error given in /home/lpa/atinfo/www/at-info/vendor/symfony/debug/Symfony/Component/Debug/ExceptionHandler.php:90\nStack trace:\n#0 [internal function]: Symfony\\Component\\Debug\\ExceptionHandler->handle(Object(Error))\n#1 {main}\n  thrown in /home/lpa/atinfo/www/at-info/vendor/symfony/debug/Symfony/Component/Debug/ExceptionHandler.php on line 90
[Sun May 22 17:52:29.996494 2016] [:error] [pid 5580] [client 127.0.0.1:50256] PHP Fatal error:  Uncaught TypeError: Argument 1 passed to Symfony\\Component\\Debug\\ExceptionHandler::handle() must be an instance of Exception, instance of Error given in /home/lpa/atinfo/www/at-info/vendor/symfony/debug/Symfony/Component/Debug/ExceptionHandler.php:90\nStack trace:\n#0 [internal function]: Symfony\\Component\\Debug\\ExceptionHandler->handle(Object(Error))\n#1 {main}\n  thrown in /home/lpa/atinfo/www/at-info/vendor/symfony/debug/Symfony/Component/Debug/ExceptionHandler.php on line 90
[Sun May 22 17:52:30.172022 2016] [:error] [pid 5737] [client 127.0.0.1:50258] PHP Fatal error:  Uncaught TypeError: Argument 1 passed to Symfony\\Component\\Debug\\ExceptionHandler::handle() must be an instance of Exception, instance of Error given in /home/lpa/atinfo/www/at-info/vendor/symfony/debug/Symfony/Component/Debug/ExceptionHandler.php:90\nStack trace:\n#0 [internal function]: Symfony\\Component\\Debug\\ExceptionHandler->handle(Object(Error))\n#1 {main}\n  thrown in /home/lpa/atinfo/www/at-info/vendor/symfony/debug/Symfony/Component/Debug/ExceptionHandler.php on line 90
[Sun May 22 17:52:30.411777 2016] [:error] [pid 5579] [client 127.0.0.1:50260] PHP Fatal error:  Uncaught TypeError: Argument 1 passed to Symfony\\Component\\Debug\\ExceptionHandler::handle() must be an instance of Exception, instance of Error given in /home/lpa/atinfo/www/at-info/vendor/symfony/debug/Symfony/Component/Debug/ExceptionHandler.php:90\nStack trace:\n#0 [internal function]: Symfony\\Component\\Debug\\ExceptionHandler->handle(Object(Error))\n#1 {main}\n  thrown in /home/lpa/atinfo/www/at-info/vendor/symfony/debug/Symfony/Component/Debug/ExceptionHandler.php on line 90
[Sun May 22 17:53:52.700638 2016] [:error] [pid 5739] [client 127.0.0.1:50308] PHP Fatal error:  Uncaught TypeError: Argument 1 passed to Symfony\\Component\\Debug\\ExceptionHandler::handle() must be an instance of Exception, instance of Error given in /home/lpa/atinfo/www/at-info/vendor/symfony/debug/Symfony/Component/Debug/ExceptionHandler.php:90\nStack trace:\n#0 [internal function]: Symfony\\Component\\Debug\\ExceptionHandler->handle(Object(Error))\n#1 {main}\n  thrown in /home/lpa/atinfo/www/at-info/vendor/symfony/debug/Symfony/Component/Debug/ExceptionHandler.php on line 90
[Sun May 22 17:53:53.810998 2016] [:error] [pid 5738] [client 127.0.0.1:50310] PHP Fatal error:  Uncaught TypeError: Argument 1 passed to Symfony\\Component\\Debug\\ExceptionHandler::handle() must be an instance of Exception, instance of Error given in /home/lpa/atinfo/www/at-info/vendor/symfony/debug/Symfony/Component/Debug/ExceptionHandler.php:90\nStack trace:\n#0 [internal function]: Symfony\\Component\\Debug\\ExceptionHandler->handle(Object(Error))\n#1 {main}\n  thrown in /home/lpa/atinfo/www/at-info/vendor/symfony/debug/Symfony/Component/Debug/ExceptionHandler.php on line 90
[Sun May 22 17:53:53.955889 2016] [:error] [pid 6751] [client 127.0.0.1:50312] PHP Fatal error:  Uncaught TypeError: Argument 1 passed to Symfony\\Component\\Debug\\ExceptionHandler::handle() must be an instance of Exception, instance of Error given in /home/lpa/atinfo/www/at-info/vendor/symfony/debug/Symfony/Component/Debug/ExceptionHandler.php:90\nStack trace:\n#0 [internal function]: Symfony\\Component\\Debug\\ExceptionHandler->handle(Object(Error))\n#1 {main}\n  thrown in /home/lpa/atinfo/www/at-info/vendor/symfony/debug/Symfony/Component/Debug/ExceptionHandler.php on line 90
[Sun May 22 17:54:03.399579 2016] [:error] [pid 5737] [client 127.0.0.1:50318] PHP Fatal error:  Uncaught TypeError: Argument 1 passed to Symfony\\Component\\Debug\\ExceptionHandler::handle() must be an instance of Exception, instance of Error given in /home/lpa/atinfo/www/at-info/vendor/symfony/debug/Symfony/Component/Debug/ExceptionHandler.php:90\nStack trace:\n#0 [internal function]: Symfony\\Component\\Debug\\ExceptionHandler->handle(Object(Error))\n#1 {main}\n  thrown in /home/lpa/atinfo/www/at-info/vendor/symfony/debug/Symfony/Component/Debug/ExceptionHandler.php on line 90
[Sun May 22 17:54:04.985647 2016] [:error] [pid 5581] [client 127.0.0.1:50320] PHP Fatal error:  Uncaught TypeError: Argument 1 passed to Symfony\\Component\\Debug\\ExceptionHandler::handle() must be an instance of Exception, instance of Error given in /home/lpa/atinfo/www/at-info/vendor/symfony/debug/Symfony/Component/Debug/ExceptionHandler.php:90\nStack trace:\n#0 [internal function]: Symfony\\Component\\Debug\\ExceptionHandler->handle(Object(Error))\n#1 {main}\n  thrown in /home/lpa/atinfo/www/at-info/vendor/symfony/debug/Symfony/Component/Debug/ExceptionHandler.php on line 90
[Sun May 22 17:54:05.040845 2016] [:error] [pid 5586] [client 127.0.0.1:50322] PHP Fatal error:  Uncaught TypeError: Argument 1 passed to Symfony\\Component\\Debug\\ExceptionHandler::handle() must be an instance of Exception, instance of Error given in /home/lpa/atinfo/www/at-info/vendor/symfony/debug/Symfony/Component/Debug/ExceptionHandler.php:90\nStack trace:\n#0 [internal function]: Symfony\\Component\\Debug\\ExceptionHandler->handle(Object(Error))\n#1 {main}\n  thrown in /home/lpa/atinfo/www/at-info/vendor/symfony/debug/Symfony/Component/Debug/ExceptionHandler.php on line 90
[Sun May 22 17:54:05.165678 2016] [:error] [pid 5583] [client 127.0.0.1:50324] PHP Fatal error:  Uncaught TypeError: Argument 1 passed to Symfony\\Component\\Debug\\ExceptionHandler::handle() must be an instance of Exception, instance of Error given in /home/lpa/atinfo/www/at-info/vendor/symfony/debug/Symfony/Component/Debug/ExceptionHandler.php:90\nStack trace:\n#0 [internal function]: Symfony\\Component\\Debug\\ExceptionHandler->handle(Object(Error))\n#1 {main}\n  thrown in /home/lpa/atinfo/www/at-info/vendor/symfony/debug/Symfony/Component/Debug/ExceptionHandler.php on line 90
[Sun May 22 17:54:05.329881 2016] [:error] [pid 5580] [client 127.0.0.1:50326] PHP Fatal error:  Uncaught TypeError: Argument 1 passed to Symfony\\Component\\Debug\\ExceptionHandler::handle() must be an instance of Exception, instance of Error given in /home/lpa/atinfo/www/at-info/vendor/symfony/debug/Symfony/Component/Debug/ExceptionHandler.php:90\nStack trace:\n#0 [internal function]: Symfony\\Component\\Debug\\ExceptionHandler->handle(Object(Error))\n#1 {main}\n  thrown in /home/lpa/atinfo/www/at-info/vendor/symfony/debug/Symfony/Component/Debug/ExceptionHandler.php on line 90
[Sun May 22 17:54:05.533833 2016] [:error] [pid 5739] [client 127.0.0.1:50328] PHP Fatal error:  Uncaught TypeError: Argument 1 passed to Symfony\\Component\\Debug\\ExceptionHandler::handle() must be an instance of Exception, instance of Error given in /home/lpa/atinfo/www/at-info/vendor/symfony/debug/Symfony/Component/Debug/ExceptionHandler.php:90\nStack trace:\n#0 [internal function]: Symfony\\Component\\Debug\\ExceptionHandler->handle(Object(Error))\n#1 {main}\n  thrown in /home/lpa/atinfo/www/at-info/vendor/symfony/debug/Symfony/Component/Debug/ExceptionHandler.php on line 90
[Sun May 22 17:54:05.722519 2016] [:error] [pid 5738] [client 127.0.0.1:50330] PHP Fatal error:  Uncaught TypeError: Argument 1 passed to Symfony\\Component\\Debug\\ExceptionHandler::handle() must be an instance of Exception, instance of Error given in /home/lpa/atinfo/www/at-info/vendor/symfony/debug/Symfony/Component/Debug/ExceptionHandler.php:90\nStack trace:\n#0 [internal function]: Symfony\\Component\\Debug\\ExceptionHandler->handle(Object(Error))\n#1 {main}\n  thrown in /home/lpa/atinfo/www/at-info/vendor/symfony/debug/Symfony/Component/Debug/ExceptionHandler.php on line 90
[Sun May 22 17:54:05.881052 2016] [:error] [pid 5582] [client 127.0.0.1:50334] PHP Fatal error:  Uncaught TypeError: Argument 1 passed to Symfony\\Component\\Debug\\ExceptionHandler::handle() must be an instance of Exception, instance of Error given in /home/lpa/atinfo/www/at-info/vendor/symfony/debug/Symfony/Component/Debug/ExceptionHandler.php:90\nStack trace:\n#0 [internal function]: Symfony\\Component\\Debug\\ExceptionHandler->handle(Object(Error))\n#1 {main}\n  thrown in /home/lpa/atinfo/www/at-info/vendor/symfony/debug/Symfony/Component/Debug/ExceptionHandler.php on line 90
[Sun May 22 17:54:05.926212 2016] [:error] [pid 5579] [client 127.0.0.1:50336] PHP Fatal error:  Uncaught TypeError: Argument 1 passed to Symfony\\Component\\Debug\\ExceptionHandler::handle() must be an instance of Exception, instance of Error given in /home/lpa/atinfo/www/at-info/vendor/symfony/debug/Symfony/Component/Debug/ExceptionHandler.php:90\nStack trace:\n#0 [internal function]: Symfony\\Component\\Debug\\ExceptionHandler->handle(Object(Error))\n#1 {main}\n  thrown in /home/lpa/atinfo/www/at-info/vendor/symfony/debug/Symfony/Component/Debug/ExceptionHandler.php on line 90
[Sun May 22 17:54:09.083599 2016] [:error] [pid 5737] [client 127.0.0.1:50338] PHP Fatal error:  Uncaught TypeError: Argument 1 passed to Symfony\\Component\\Debug\\ExceptionHandler::handle() must be an instance of Exception, instance of Error given in /home/lpa/atinfo/www/at-info/vendor/symfony/debug/Symfony/Component/Debug/ExceptionHandler.php:90\nStack trace:\n#0 [internal function]: Symfony\\Component\\Debug\\ExceptionHandler->handle(Object(Error))\n#1 {main}\n  thrown in /home/lpa/atinfo/www/at-info/vendor/symfony/debug/Symfony/Component/Debug/ExceptionHandler.php on line 90
[Sun May 22 17:56:07.942777 2016] [:error] [pid 5739] [client 127.0.0.1:50390] PHP Fatal error:  Uncaught TypeError: Argument 1 passed to Symfony\\Component\\Debug\\ExceptionHandler::handle() must be an instance of Exception, instance of Error given in /home/lpa/atinfo/www/at-info/vendor/symfony/debug/Symfony/Component/Debug/ExceptionHandler.php:90\nStack trace:\n#0 [internal function]: Symfony\\Component\\Debug\\ExceptionHandler->handle(Object(Error))\n#1 {main}\n  thrown in /home/lpa/atinfo/www/at-info/vendor/symfony/debug/Symfony/Component/Debug/ExceptionHandler.php on line 90
[Sun May 22 17:56:08.898999 2016] [:error] [pid 5738] [client 127.0.0.1:50392] PHP Fatal error:  Uncaught TypeError: Argument 1 passed to Symfony\\Component\\Debug\\ExceptionHandler::handle() must be an instance of Exception, instance of Error given in /home/lpa/atinfo/www/at-info/vendor/symfony/debug/Symfony/Component/Debug/ExceptionHandler.php:90\nStack trace:\n#0 [internal function]: Symfony\\Component\\Debug\\ExceptionHandler->handle(Object(Error))\n#1 {main}\n  thrown in /home/lpa/atinfo/www/at-info/vendor/symfony/debug/Symfony/Component/Debug/ExceptionHandler.php on line 90
[Sun May 22 17:56:09.072767 2016] [:error] [pid 6751] [client 127.0.0.1:50394] PHP Fatal error:  Uncaught TypeError: Argument 1 passed to Symfony\\Component\\Debug\\ExceptionHandler::handle() must be an instance of Exception, instance of Error given in /home/lpa/atinfo/www/at-info/vendor/symfony/debug/Symfony/Component/Debug/ExceptionHandler.php:90\nStack trace:\n#0 [internal function]: Symfony\\Component\\Debug\\ExceptionHandler->handle(Object(Error))\n#1 {main}\n  thrown in /home/lpa/atinfo/www/at-info/vendor/symfony/debug/Symfony/Component/Debug/ExceptionHandler.php on line 90
[Sun May 22 17:56:49.919519 2016] [:error] [pid 5579] [client 127.0.0.1:50402] PHP Fatal error:  Uncaught TypeError: Argument 1 passed to Symfony\\Component\\Debug\\ExceptionHandler::handle() must be an instance of Exception, instance of ParseError given in /home/lpa/atinfo/www/at-info/vendor/symfony/debug/Symfony/Component/Debug/ExceptionHandler.php:90\nStack trace:\n#0 [internal function]: Symfony\\Component\\Debug\\ExceptionHandler->handle(Object(ParseError))\n#1 {main}\n  thrown in /home/lpa/atinfo/www/at-info/vendor/symfony/debug/Symfony/Component/Debug/ExceptionHandler.php on line 90
[Sun May 22 17:56:50.799550 2016] [:error] [pid 5582] [client 127.0.0.1:50404] PHP Fatal error:  Uncaught TypeError: Argument 1 passed to Symfony\\Component\\Debug\\ExceptionHandler::handle() must be an instance of Exception, instance of ParseError given in /home/lpa/atinfo/www/at-info/vendor/symfony/debug/Symfony/Component/Debug/ExceptionHandler.php:90\nStack trace:\n#0 [internal function]: Symfony\\Component\\Debug\\ExceptionHandler->handle(Object(ParseError))\n#1 {main}\n  thrown in /home/lpa/atinfo/www/at-info/vendor/symfony/debug/Symfony/Component/Debug/ExceptionHandler.php on line 90
[Sun May 22 17:56:51.536974 2016] [:error] [pid 5580] [client 127.0.0.1:50406] PHP Fatal error:  Uncaught TypeError: Argument 1 passed to Symfony\\Component\\Debug\\ExceptionHandler::handle() must be an instance of Exception, instance of ParseError given in /home/lpa/atinfo/www/at-info/vendor/symfony/debug/Symfony/Component/Debug/ExceptionHandler.php:90\nStack trace:\n#0 [internal function]: Symfony\\Component\\Debug\\ExceptionHandler->handle(Object(ParseError))\n#1 {main}\n  thrown in /home/lpa/atinfo/www/at-info/vendor/symfony/debug/Symfony/Component/Debug/ExceptionHandler.php on line 90
[Sun May 22 17:56:54.341290 2016] [:error] [pid 5583] [client 127.0.0.1:50408] PHP Fatal error:  Uncaught TypeError: Argument 1 passed to Symfony\\Component\\Debug\\ExceptionHandler::handle() must be an instance of Exception, instance of ParseError given in /home/lpa/atinfo/www/at-info/vendor/symfony/debug/Symfony/Component/Debug/ExceptionHandler.php:90\nStack trace:\n#0 [internal function]: Symfony\\Component\\Debug\\ExceptionHandler->handle(Object(ParseError))\n#1 {main}\n  thrown in /home/lpa/atinfo/www/at-info/vendor/symfony/debug/Symfony/Component/Debug/ExceptionHandler.php on line 90
[Sun May 22 17:57:03.948588 2016] [:error] [pid 5586] [client 127.0.0.1:50410] PHP Fatal error:  Uncaught TypeError: Argument 1 passed to Symfony\\Component\\Debug\\ExceptionHandler::handle() must be an instance of Exception, instance of ParseError given in /home/lpa/atinfo/www/at-info/vendor/symfony/debug/Symfony/Component/Debug/ExceptionHandler.php:90\nStack trace:\n#0 [internal function]: Symfony\\Component\\Debug\\ExceptionHandler->handle(Object(ParseError))\n#1 {main}\n  thrown in /home/lpa/atinfo/www/at-info/vendor/symfony/debug/Symfony/Component/Debug/ExceptionHandler.php on line 90
[Sun May 22 17:57:04.778297 2016] [:error] [pid 5581] [client 127.0.0.1:50412] PHP Fatal error:  Uncaught TypeError: Argument 1 passed to Symfony\\Component\\Debug\\ExceptionHandler::handle() must be an instance of Exception, instance of ParseError given in /home/lpa/atinfo/www/at-info/vendor/symfony/debug/Symfony/Component/Debug/ExceptionHandler.php:90\nStack trace:\n#0 [internal function]: Symfony\\Component\\Debug\\ExceptionHandler->handle(Object(ParseError))\n#1 {main}\n  thrown in /home/lpa/atinfo/www/at-info/vendor/symfony/debug/Symfony/Component/Debug/ExceptionHandler.php on line 90
[Sun May 22 17:59:35.102245 2016] [:error] [pid 5579] [client 127.0.0.1:50486] PHP Fatal error:  Uncaught TypeError: Argument 1 passed to Symfony\\Component\\Debug\\ExceptionHandler::handle() must be an instance of Exception, instance of Error given in /home/lpa/atinfo/www/at-info/vendor/symfony/debug/Symfony/Component/Debug/ExceptionHandler.php:90\nStack trace:\n#0 [internal function]: Symfony\\Component\\Debug\\ExceptionHandler->handle(Object(Error))\n#1 {main}\n  thrown in /home/lpa/atinfo/www/at-info/vendor/symfony/debug/Symfony/Component/Debug/ExceptionHandler.php on line 90
[Sun May 22 17:59:36.209461 2016] [:error] [pid 5738] [client 127.0.0.1:50488] PHP Fatal error:  Uncaught TypeError: Argument 1 passed to Symfony\\Component\\Debug\\ExceptionHandler::handle() must be an instance of Exception, instance of Error given in /home/lpa/atinfo/www/at-info/vendor/symfony/debug/Symfony/Component/Debug/ExceptionHandler.php:90\nStack trace:\n#0 [internal function]: Symfony\\Component\\Debug\\ExceptionHandler->handle(Object(Error))\n#1 {main}\n  thrown in /home/lpa/atinfo/www/at-info/vendor/symfony/debug/Symfony/Component/Debug/ExceptionHandler.php on line 90
[Sun May 22 18:01:09.944213 2016] [:error] [pid 5580] [client 127.0.0.1:50564] PHP Fatal error:  Uncaught TypeError: Argument 1 passed to Symfony\\Component\\Debug\\ExceptionHandler::handle() must be an instance of Exception, instance of Error given in /home/lpa/atinfo/www/at-info/vendor/symfony/debug/Symfony/Component/Debug/ExceptionHandler.php:90\nStack trace:\n#0 [internal function]: Symfony\\Component\\Debug\\ExceptionHandler->handle(Object(Error))\n#1 {main}\n  thrown in /home/lpa/atinfo/www/at-info/vendor/symfony/debug/Symfony/Component/Debug/ExceptionHandler.php on line 90
[Sun May 22 18:02:02.093744 2016] [:error] [pid 5586] [client 127.0.0.1:50572] PHP Fatal error:  Uncaught TypeError: Argument 1 passed to Symfony\\Component\\Debug\\ExceptionHandler::handle() must be an instance of Exception, instance of Error given in /home/lpa/atinfo/www/at-info/vendor/symfony/debug/Symfony/Component/Debug/ExceptionHandler.php:90\nStack trace:\n#0 [internal function]: Symfony\\Component\\Debug\\ExceptionHandler->handle(Object(Error))\n#1 {main}\n  thrown in /home/lpa/atinfo/www/at-info/vendor/symfony/debug/Symfony/Component/Debug/ExceptionHandler.php on line 90
[Sun May 22 18:02:02.868631 2016] [:error] [pid 5583] [client 127.0.0.1:50574] PHP Fatal error:  Uncaught TypeError: Argument 1 passed to Symfony\\Component\\Debug\\ExceptionHandler::handle() must be an instance of Exception, instance of Error given in /home/lpa/atinfo/www/at-info/vendor/symfony/debug/Symfony/Component/Debug/ExceptionHandler.php:90\nStack trace:\n#0 [internal function]: Symfony\\Component\\Debug\\ExceptionHandler->handle(Object(Error))\n#1 {main}\n  thrown in /home/lpa/atinfo/www/at-info/vendor/symfony/debug/Symfony/Component/Debug/ExceptionHandler.php on line 90
[Sun May 22 18:02:02.998142 2016] [:error] [pid 6751] [client 127.0.0.1:50578] PHP Fatal error:  Uncaught TypeError: Argument 1 passed to Symfony\\Component\\Debug\\ExceptionHandler::handle() must be an instance of Exception, instance of Error given in /home/lpa/atinfo/www/at-info/vendor/symfony/debug/Symfony/Component/Debug/ExceptionHandler.php:90\nStack trace:\n#0 [internal function]: Symfony\\Component\\Debug\\ExceptionHandler->handle(Object(Error))\n#1 {main}\n  thrown in /home/lpa/atinfo/www/at-info/vendor/symfony/debug/Symfony/Component/Debug/ExceptionHandler.php on line 90
[Sun May 22 18:02:03.125344 2016] [:error] [pid 5581] [client 127.0.0.1:50576] PHP Fatal error:  Uncaught TypeError: Argument 1 passed to Symfony\\Component\\Debug\\ExceptionHandler::handle() must be an instance of Exception, instance of Error given in /home/lpa/atinfo/www/at-info/vendor/symfony/debug/Symfony/Component/Debug/ExceptionHandler.php:90\nStack trace:\n#0 [internal function]: Symfony\\Component\\Debug\\ExceptionHandler->handle(Object(Error))\n#1 {main}\n  thrown in /home/lpa/atinfo/www/at-info/vendor/symfony/debug/Symfony/Component/Debug/ExceptionHandler.php on line 90
[Mon May 30 12:31:51.461907 2016] [:error] [pid 12255] [client 127.0.0.1:39890] PHP Notice:  Object of class Symfony\\Component\\HttpFoundation\\Request could not be converted to int in /home/lpa/atinfo/www/at-info/vendor/symfony/http-foundation/Response.php on line 454, referer: http://at-info/index.php/services
[Mon May 30 12:31:51.462869 2016] [:error] [pid 12255] [client 127.0.0.1:39890] PHP Fatal error:  Uncaught InvalidArgumentException: The HTTP status code "1" is not valid. in /home/lpa/atinfo/www/at-info/vendor/symfony/http-foundation/Response.php:456\nStack trace:\n#0 /home/lpa/atinfo/www/at-info/vendor/symfony/http-foundation/Response.php(200): Symfony\\Component\\HttpFoundation\\Response->setStatusCode(1)\n#1 /home/lpa/atinfo/www/at-info/src/controllers.php(116): Symfony\\Component\\HttpFoundation\\Response->__construct('<!doctype html>...', Object(Symfony\\Component\\HttpFoundation\\Request))\n#2 [internal function]: {closure}(Object(Symfony\\Component\\HttpKernel\\Exception\\NotFoundHttpException), Object(Symfony\\Component\\HttpFoundation\\Request), 404)\n#3 /home/lpa/atinfo/www/at-info/vendor/silex/silex/src/Silex/ExceptionListenerWrapper.php(53): call_user_func(Object(Closure), Object(Symfony\\Component\\HttpKernel\\Exception\\NotFoundHttpException), Object(Symfony\\Component\\HttpFoundation\\Request), 404)\n#4 [internal function]: Silex\\ExceptionListenerWrapper->__invoke(Object(Symfony\\Component\\HttpKernel\\Event\\GetResponseF in /home/lpa/atinfo/www/at-info/vendor/symfony/http-foundation/Response.php on line 456, referer: http://at-info/index.php/services
[Mon May 30 12:31:51.494080 2016] [:error] [pid 13068] [client 127.0.0.1:39892] PHP Notice:  Object of class Symfony\\Component\\HttpFoundation\\Request could not be converted to int in /home/lpa/atinfo/www/at-info/vendor/symfony/http-foundation/Response.php on line 454, referer: http://at-info/index.php/services
[Mon May 30 12:31:51.494155 2016] [:error] [pid 13068] [client 127.0.0.1:39892] PHP Fatal error:  Uncaught InvalidArgumentException: The HTTP status code "1" is not valid. in /home/lpa/atinfo/www/at-info/vendor/symfony/http-foundation/Response.php:456\nStack trace:\n#0 /home/lpa/atinfo/www/at-info/vendor/symfony/http-foundation/Response.php(200): Symfony\\Component\\HttpFoundation\\Response->setStatusCode(1)\n#1 /home/lpa/atinfo/www/at-info/src/controllers.php(116): Symfony\\Component\\HttpFoundation\\Response->__construct('<!doctype html>...', Object(Symfony\\Component\\HttpFoundation\\Request))\n#2 [internal function]: {closure}(Object(Symfony\\Component\\HttpKernel\\Exception\\NotFoundHttpException), Object(Symfony\\Component\\HttpFoundation\\Request), 404)\n#3 /home/lpa/atinfo/www/at-info/vendor/silex/silex/src/Silex/ExceptionListenerWrapper.php(53): call_user_func(Object(Closure), Object(Symfony\\Component\\HttpKernel\\Exception\\NotFoundHttpException), Object(Symfony\\Component\\HttpFoundation\\Request), 404)\n#4 [internal function]: Silex\\ExceptionListenerWrapper->__invoke(Object(Symfony\\Component\\HttpKernel\\Event\\GetResponseF in /home/lpa/atinfo/www/at-info/vendor/symfony/http-foundation/Response.php on line 456, referer: http://at-info/index.php/services
[Mon May 30 12:31:51.516495 2016] [:error] [pid 12251] [client 127.0.0.1:39894] PHP Notice:  Object of class Symfony\\Component\\HttpFoundation\\Request could not be converted to int in /home/lpa/atinfo/www/at-info/vendor/symfony/http-foundation/Response.php on line 454, referer: http://at-info/index.php/services
[Mon May 30 12:31:51.516578 2016] [:error] [pid 12251] [client 127.0.0.1:39894] PHP Fatal error:  Uncaught InvalidArgumentException: The HTTP status code "1" is not valid. in /home/lpa/atinfo/www/at-info/vendor/symfony/http-foundation/Response.php:456\nStack trace:\n#0 /home/lpa/atinfo/www/at-info/vendor/symfony/http-foundation/Response.php(200): Symfony\\Component\\HttpFoundation\\Response->setStatusCode(1)\n#1 /home/lpa/atinfo/www/at-info/src/controllers.php(116): Symfony\\Component\\HttpFoundation\\Response->__construct('<!doctype html>...', Object(Symfony\\Component\\HttpFoundation\\Request))\n#2 [internal function]: {closure}(Object(Symfony\\Component\\HttpKernel\\Exception\\NotFoundHttpException), Object(Symfony\\Component\\HttpFoundation\\Request), 404)\n#3 /home/lpa/atinfo/www/at-info/vendor/silex/silex/src/Silex/ExceptionListenerWrapper.php(53): call_user_func(Object(Closure), Object(Symfony\\Component\\HttpKernel\\Exception\\NotFoundHttpException), Object(Symfony\\Component\\HttpFoundation\\Request), 404)\n#4 [internal function]: Silex\\ExceptionListenerWrapper->__invoke(Object(Symfony\\Component\\HttpKernel\\Event\\GetResponseF in /home/lpa/atinfo/www/at-info/vendor/symfony/http-foundation/Response.php on line 456, referer: http://at-info/index.php/services
[Mon May 30 12:31:51.520743 2016] [:error] [pid 12252] [client 127.0.0.1:39896] PHP Notice:  Object of class Symfony\\Component\\HttpFoundation\\Request could not be converted to int in /home/lpa/atinfo/www/at-info/vendor/symfony/http-foundation/Response.php on line 454, referer: http://at-info/index.php/services
[Mon May 30 12:31:51.520839 2016] [:error] [pid 12252] [client 127.0.0.1:39896] PHP Fatal error:  Uncaught InvalidArgumentException: The HTTP status code "1" is not valid. in /home/lpa/atinfo/www/at-info/vendor/symfony/http-foundation/Response.php:456\nStack trace:\n#0 /home/lpa/atinfo/www/at-info/vendor/symfony/http-foundation/Response.php(200): Symfony\\Component\\HttpFoundation\\Response->setStatusCode(1)\n#1 /home/lpa/atinfo/www/at-info/src/controllers.php(116): Symfony\\Component\\HttpFoundation\\Response->__construct('<!doctype html>...', Object(Symfony\\Component\\HttpFoundation\\Request))\n#2 [internal function]: {closure}(Object(Symfony\\Component\\HttpKernel\\Exception\\NotFoundHttpException), Object(Symfony\\Component\\HttpFoundation\\Request), 404)\n#3 /home/lpa/atinfo/www/at-info/vendor/silex/silex/src/Silex/ExceptionListenerWrapper.php(53): call_user_func(Object(Closure), Object(Symfony\\Component\\HttpKernel\\Exception\\NotFoundHttpException), Object(Symfony\\Component\\HttpFoundation\\Request), 404)\n#4 [internal function]: Silex\\ExceptionListenerWrapper->__invoke(Object(Symfony\\Component\\HttpKernel\\Event\\GetResponseF in /home/lpa/atinfo/www/at-info/vendor/symfony/http-foundation/Response.php on line 456, referer: http://at-info/index.php/services
[Mon May 30 12:31:51.533352 2016] [:error] [pid 13239] [client 127.0.0.1:39898] PHP Notice:  Object of class Symfony\\Component\\HttpFoundation\\Request could not be converted to int in /home/lpa/atinfo/www/at-info/vendor/symfony/http-foundation/Response.php on line 454, referer: http://at-info/index.php/services
[Mon May 30 12:31:51.533447 2016] [:error] [pid 13239] [client 127.0.0.1:39898] PHP Fatal error:  Uncaught InvalidArgumentException: The HTTP status code "1" is not valid. in /home/lpa/atinfo/www/at-info/vendor/symfony/http-foundation/Response.php:456\nStack trace:\n#0 /home/lpa/atinfo/www/at-info/vendor/symfony/http-foundation/Response.php(200): Symfony\\Component\\HttpFoundation\\Response->setStatusCode(1)\n#1 /home/lpa/atinfo/www/at-info/src/controllers.php(116): Symfony\\Component\\HttpFoundation\\Response->__construct('<!doctype html>...', Object(Symfony\\Component\\HttpFoundation\\Request))\n#2 [internal function]: {closure}(Object(Symfony\\Component\\HttpKernel\\Exception\\NotFoundHttpException), Object(Symfony\\Component\\HttpFoundation\\Request), 404)\n#3 /home/lpa/atinfo/www/at-info/vendor/silex/silex/src/Silex/ExceptionListenerWrapper.php(53): call_user_func(Object(Closure), Object(Symfony\\Component\\HttpKernel\\Exception\\NotFoundHttpException), Object(Symfony\\Component\\HttpFoundation\\Request), 404)\n#4 [internal function]: Silex\\ExceptionListenerWrapper->__invoke(Object(Symfony\\Component\\HttpKernel\\Event\\GetResponseF in /home/lpa/atinfo/www/at-info/vendor/symfony/http-foundation/Response.php on line 456, referer: http://at-info/index.php/services
[Mon May 30 12:31:51.601914 2016] [:error] [pid 12254] [client 127.0.0.1:39900] PHP Notice:  Object of class Symfony\\Component\\HttpFoundation\\Request could not be converted to int in /home/lpa/atinfo/www/at-info/vendor/symfony/http-foundation/Response.php on line 454, referer: http://at-info/index.php/services
[Mon May 30 12:31:51.601999 2016] [:error] [pid 12254] [client 127.0.0.1:39900] PHP Fatal error:  Uncaught InvalidArgumentException: The HTTP status code "1" is not valid. in /home/lpa/atinfo/www/at-info/vendor/symfony/http-foundation/Response.php:456\nStack trace:\n#0 /home/lpa/atinfo/www/at-info/vendor/symfony/http-foundation/Response.php(200): Symfony\\Component\\HttpFoundation\\Response->setStatusCode(1)\n#1 /home/lpa/atinfo/www/at-info/src/controllers.php(116): Symfony\\Component\\HttpFoundation\\Response->__construct('<!doctype html>...', Object(Symfony\\Component\\HttpFoundation\\Request))\n#2 [internal function]: {closure}(Object(Symfony\\Component\\HttpKernel\\Exception\\NotFoundHttpException), Object(Symfony\\Component\\HttpFoundation\\Request), 404)\n#3 /home/lpa/atinfo/www/at-info/vendor/silex/silex/src/Silex/ExceptionListenerWrapper.php(53): call_user_func(Object(Closure), Object(Symfony\\Component\\HttpKernel\\Exception\\NotFoundHttpException), Object(Symfony\\Component\\HttpFoundation\\Request), 404)\n#4 [internal function]: Silex\\ExceptionListenerWrapper->__invoke(Object(Symfony\\Component\\HttpKernel\\Event\\GetResponseF in /home/lpa/atinfo/www/at-info/vendor/symfony/http-foundation/Response.php on line 456, referer: http://at-info/index.php/services
[Mon May 30 12:31:51.694356 2016] [:error] [pid 12255] [client 127.0.0.1:39902] PHP Notice:  Object of class Symfony\\Component\\HttpFoundation\\Request could not be converted to int in /home/lpa/atinfo/www/at-info/vendor/symfony/http-foundation/Response.php on line 454, referer: http://at-info/index.php/services
[Mon May 30 12:31:51.694467 2016] [:error] [pid 12255] [client 127.0.0.1:39902] PHP Fatal error:  Uncaught InvalidArgumentException: The HTTP status code "1" is not valid. in /home/lpa/atinfo/www/at-info/vendor/symfony/http-foundation/Response.php:456\nStack trace:\n#0 /home/lpa/atinfo/www/at-info/vendor/symfony/http-foundation/Response.php(200): Symfony\\Component\\HttpFoundation\\Response->setStatusCode(1)\n#1 /home/lpa/atinfo/www/at-info/src/controllers.php(116): Symfony\\Component\\HttpFoundation\\Response->__construct('<!doctype html>...', Object(Symfony\\Component\\HttpFoundation\\Request))\n#2 [internal function]: {closure}(Object(Symfony\\Component\\HttpKernel\\Exception\\NotFoundHttpException), Object(Symfony\\Component\\HttpFoundation\\Request), 404)\n#3 /home/lpa/atinfo/www/at-info/vendor/silex/silex/src/Silex/ExceptionListenerWrapper.php(53): call_user_func(Object(Closure), Object(Symfony\\Component\\HttpKernel\\Exception\\NotFoundHttpException), Object(Symfony\\Component\\HttpFoundation\\Request), 404)\n#4 [internal function]: Silex\\ExceptionListenerWrapper->__invoke(Object(Symfony\\Component\\HttpKernel\\Event\\GetResponseF in /home/lpa/atinfo/www/at-info/vendor/symfony/http-foundation/Response.php on line 456, referer: http://at-info/index.php/services
[Tue May 31 16:04:13.537582 2016] [:error] [pid 3332] [client 127.0.0.1:51972] PHP Notice:  Object of class Symfony\\Component\\HttpFoundation\\Request could not be converted to int in /home/lpa/atinfo/www/at-info/vendor/symfony/http-foundation/Response.php on line 454, referer: http://at-info/index.php/services
[Tue May 31 16:04:13.537582 2016] [:error] [pid 1175] [client 127.0.0.1:52026] PHP Notice:  Object of class Symfony\\Component\\HttpFoundation\\Request could not be converted to int in /home/lpa/atinfo/www/at-info/vendor/symfony/http-foundation/Response.php on line 454, referer: http://at-info/index.php/services
[Tue May 31 16:04:13.543493 2016] [:error] [pid 1175] [client 127.0.0.1:52026] PHP Fatal error:  Uncaught InvalidArgumentException: The HTTP status code "1" is not valid. in /home/lpa/atinfo/www/at-info/vendor/symfony/http-foundation/Response.php:456\nStack trace:\n#0 /home/lpa/atinfo/www/at-info/vendor/symfony/http-foundation/Response.php(200): Symfony\\Component\\HttpFoundation\\Response->setStatusCode(1)\n#1 /home/lpa/atinfo/www/at-info/src/controllers.php(105): Symfony\\Component\\HttpFoundation\\Response->__construct('<!doctype html>...', Object(Symfony\\Component\\HttpFoundation\\Request))\n#2 [internal function]: {closure}(Object(Symfony\\Component\\HttpKernel\\Exception\\NotFoundHttpException), Object(Symfony\\Component\\HttpFoundation\\Request), 404)\n#3 /home/lpa/atinfo/www/at-info/vendor/silex/silex/src/Silex/ExceptionListenerWrapper.php(53): call_user_func(Object(Closure), Object(Symfony\\Component\\HttpKernel\\Exception\\NotFoundHttpException), Object(Symfony\\Component\\HttpFoundation\\Request), 404)\n#4 [internal function]: Silex\\ExceptionListenerWrapper->__invoke(Object(Symfony\\Component\\HttpKernel\\Event\\GetResponseF in /home/lpa/atinfo/www/at-info/vendor/symfony/http-foundation/Response.php on line 456, referer: http://at-info/index.php/services
[Tue May 31 16:04:13.543493 2016] [:error] [pid 3332] [client 127.0.0.1:51972] PHP Fatal error:  Uncaught InvalidArgumentException: The HTTP status code "1" is not valid. in /home/lpa/atinfo/www/at-info/vendor/symfony/http-foundation/Response.php:456\nStack trace:\n#0 /home/lpa/atinfo/www/at-info/vendor/symfony/http-foundation/Response.php(200): Symfony\\Component\\HttpFoundation\\Response->setStatusCode(1)\n#1 /home/lpa/atinfo/www/at-info/src/controllers.php(105): Symfony\\Component\\HttpFoundation\\Response->__construct('<!doctype html>...', Object(Symfony\\Component\\HttpFoundation\\Request))\n#2 [internal function]: {closure}(Object(Symfony\\Component\\HttpKernel\\Exception\\NotFoundHttpException), Object(Symfony\\Component\\HttpFoundation\\Request), 404)\n#3 /home/lpa/atinfo/www/at-info/vendor/silex/silex/src/Silex/ExceptionListenerWrapper.php(53): call_user_func(Object(Closure), Object(Symfony\\Component\\HttpKernel\\Exception\\NotFoundHttpException), Object(Symfony\\Component\\HttpFoundation\\Request), 404)\n#4 [internal function]: Silex\\ExceptionListenerWrapper->__invoke(Object(Symfony\\Component\\HttpKernel\\Event\\GetResponseF in /home/lpa/atinfo/www/at-info/vendor/symfony/http-foundation/Response.php on line 456, referer: http://at-info/index.php/services
[Tue May 31 16:04:13.633089 2016] [:error] [pid 3331] [client 127.0.0.1:52028] PHP Notice:  Object of class Symfony\\Component\\HttpFoundation\\Request could not be converted to int in /home/lpa/atinfo/www/at-info/vendor/symfony/http-foundation/Response.php on line 454, referer: http://at-info/index.php/services
[Tue May 31 16:04:13.633199 2016] [:error] [pid 3331] [client 127.0.0.1:52028] PHP Fatal error:  Uncaught InvalidArgumentException: The HTTP status code "1" is not valid. in /home/lpa/atinfo/www/at-info/vendor/symfony/http-foundation/Response.php:456\nStack trace:\n#0 /home/lpa/atinfo/www/at-info/vendor/symfony/http-foundation/Response.php(200): Symfony\\Component\\HttpFoundation\\Response->setStatusCode(1)\n#1 /home/lpa/atinfo/www/at-info/src/controllers.php(105): Symfony\\Component\\HttpFoundation\\Response->__construct('<!doctype html>...', Object(Symfony\\Component\\HttpFoundation\\Request))\n#2 [internal function]: {closure}(Object(Symfony\\Component\\HttpKernel\\Exception\\NotFoundHttpException), Object(Symfony\\Component\\HttpFoundation\\Request), 404)\n#3 /home/lpa/atinfo/www/at-info/vendor/silex/silex/src/Silex/ExceptionListenerWrapper.php(53): call_user_func(Object(Closure), Object(Symfony\\Component\\HttpKernel\\Exception\\NotFoundHttpException), Object(Symfony\\Component\\HttpFoundation\\Request), 404)\n#4 [internal function]: Silex\\ExceptionListenerWrapper->__invoke(Object(Symfony\\Component\\HttpKernel\\Event\\GetResponseF in /home/lpa/atinfo/www/at-info/vendor/symfony/http-foundation/Response.php on line 456, referer: http://at-info/index.php/services
[Tue May 31 16:04:13.636955 2016] [:error] [pid 3330] [client 127.0.0.1:52034] PHP Notice:  Object of class Symfony\\Component\\HttpFoundation\\Request could not be converted to int in /home/lpa/atinfo/www/at-info/vendor/symfony/http-foundation/Response.php on line 454, referer: http://at-info/index.php/services
[Tue May 31 16:04:13.637039 2016] [:error] [pid 3330] [client 127.0.0.1:52034] PHP Fatal error:  Uncaught InvalidArgumentException: The HTTP status code "1" is not valid. in /home/lpa/atinfo/www/at-info/vendor/symfony/http-foundation/Response.php:456\nStack trace:\n#0 /home/lpa/atinfo/www/at-info/vendor/symfony/http-foundation/Response.php(200): Symfony\\Component\\HttpFoundation\\Response->setStatusCode(1)\n#1 /home/lpa/atinfo/www/at-info/src/controllers.php(105): Symfony\\Component\\HttpFoundation\\Response->__construct('<!doctype html>...', Object(Symfony\\Component\\HttpFoundation\\Request))\n#2 [internal function]: {closure}(Object(Symfony\\Component\\HttpKernel\\Exception\\NotFoundHttpException), Object(Symfony\\Component\\HttpFoundation\\Request), 404)\n#3 /home/lpa/atinfo/www/at-info/vendor/silex/silex/src/Silex/ExceptionListenerWrapper.php(53): call_user_func(Object(Closure), Object(Symfony\\Component\\HttpKernel\\Exception\\NotFoundHttpException), Object(Symfony\\Component\\HttpFoundation\\Request), 404)\n#4 [internal function]: Silex\\ExceptionListenerWrapper->__invoke(Object(Symfony\\Component\\HttpKernel\\Event\\GetResponseF in /home/lpa/atinfo/www/at-info/vendor/symfony/http-foundation/Response.php on line 456, referer: http://at-info/index.php/services
[Tue May 31 16:04:13.644199 2016] [:error] [pid 1173] [client 127.0.0.1:52032] PHP Notice:  Object of class Symfony\\Component\\HttpFoundation\\Request could not be converted to int in /home/lpa/atinfo/www/at-info/vendor/symfony/http-foundation/Response.php on line 454, referer: http://at-info/index.php/services
[Tue May 31 16:04:13.646361 2016] [:error] [pid 1173] [client 127.0.0.1:52032] PHP Fatal error:  Uncaught InvalidArgumentException: The HTTP status code "1" is not valid. in /home/lpa/atinfo/www/at-info/vendor/symfony/http-foundation/Response.php:456\nStack trace:\n#0 /home/lpa/atinfo/www/at-info/vendor/symfony/http-foundation/Response.php(200): Symfony\\Component\\HttpFoundation\\Response->setStatusCode(1)\n#1 /home/lpa/atinfo/www/at-info/src/controllers.php(105): Symfony\\Component\\HttpFoundation\\Response->__construct('<!doctype html>...', Object(Symfony\\Component\\HttpFoundation\\Request))\n#2 [internal function]: {closure}(Object(Symfony\\Component\\HttpKernel\\Exception\\NotFoundHttpException), Object(Symfony\\Component\\HttpFoundation\\Request), 404)\n#3 /home/lpa/atinfo/www/at-info/vendor/silex/silex/src/Silex/ExceptionListenerWrapper.php(53): call_user_func(Object(Closure), Object(Symfony\\Component\\HttpKernel\\Exception\\NotFoundHttpException), Object(Symfony\\Component\\HttpFoundation\\Request), 404)\n#4 [internal function]: Silex\\ExceptionListenerWrapper->__invoke(Object(Symfony\\Component\\HttpKernel\\Event\\GetResponseF in /home/lpa/atinfo/www/at-info/vendor/symfony/http-foundation/Response.php on line 456, referer: http://at-info/index.php/services
[Tue May 31 16:04:14.007688 2016] [:error] [pid 1177] [client 127.0.0.1:52030] PHP Notice:  Object of class Symfony\\Component\\HttpFoundation\\Request could not be converted to int in /home/lpa/atinfo/www/at-info/vendor/symfony/http-foundation/Response.php on line 454, referer: http://at-info/index.php/services
[Tue May 31 16:04:14.007770 2016] [:error] [pid 1177] [client 127.0.0.1:52030] PHP Fatal error:  Uncaught InvalidArgumentException: The HTTP status code "1" is not valid. in /home/lpa/atinfo/www/at-info/vendor/symfony/http-foundation/Response.php:456\nStack trace:\n#0 /home/lpa/atinfo/www/at-info/vendor/symfony/http-foundation/Response.php(200): Symfony\\Component\\HttpFoundation\\Response->setStatusCode(1)\n#1 /home/lpa/atinfo/www/at-info/src/controllers.php(105): Symfony\\Component\\HttpFoundation\\Response->__construct('<!doctype html>...', Object(Symfony\\Component\\HttpFoundation\\Request))\n#2 [internal function]: {closure}(Object(Symfony\\Component\\HttpKernel\\Exception\\NotFoundHttpException), Object(Symfony\\Component\\HttpFoundation\\Request), 404)\n#3 /home/lpa/atinfo/www/at-info/vendor/silex/silex/src/Silex/ExceptionListenerWrapper.php(53): call_user_func(Object(Closure), Object(Symfony\\Component\\HttpKernel\\Exception\\NotFoundHttpException), Object(Symfony\\Component\\HttpFoundation\\Request), 404)\n#4 [internal function]: Silex\\ExceptionListenerWrapper->__invoke(Object(Symfony\\Component\\HttpKernel\\Event\\GetResponseF in /home/lpa/atinfo/www/at-info/vendor/symfony/http-foundation/Response.php on line 456, referer: http://at-info/index.php/services
[Tue May 31 16:04:17.233657 2016] [:error] [pid 2567] [client 127.0.0.1:52038] PHP Notice:  Object of class Symfony\\Component\\HttpFoundation\\Request could not be converted to int in /home/lpa/atinfo/www/at-info/vendor/symfony/http-foundation/Response.php on line 454, referer: http://at-info/index.php/services
[Tue May 31 16:04:17.233729 2016] [:error] [pid 2567] [client 127.0.0.1:52038] PHP Fatal error:  Uncaught InvalidArgumentException: The HTTP status code "1" is not valid. in /home/lpa/atinfo/www/at-info/vendor/symfony/http-foundation/Response.php:456\nStack trace:\n#0 /home/lpa/atinfo/www/at-info/vendor/symfony/http-foundation/Response.php(200): Symfony\\Component\\HttpFoundation\\Response->setStatusCode(1)\n#1 /home/lpa/atinfo/www/at-info/src/controllers.php(105): Symfony\\Component\\HttpFoundation\\Response->__construct('<!doctype html>...', Object(Symfony\\Component\\HttpFoundation\\Request))\n#2 [internal function]: {closure}(Object(Symfony\\Component\\HttpKernel\\Exception\\NotFoundHttpException), Object(Symfony\\Component\\HttpFoundation\\Request), 404)\n#3 /home/lpa/atinfo/www/at-info/vendor/silex/silex/src/Silex/ExceptionListenerWrapper.php(53): call_user_func(Object(Closure), Object(Symfony\\Component\\HttpKernel\\Exception\\NotFoundHttpException), Object(Symfony\\Component\\HttpFoundation\\Request), 404)\n#4 [internal function]: Silex\\ExceptionListenerWrapper->__invoke(Object(Symfony\\Component\\HttpKernel\\Event\\GetResponseF in /home/lpa/atinfo/www/at-info/vendor/symfony/http-foundation/Response.php on line 456, referer: http://at-info/index.php/services
[Tue Jun 14 12:30:50.017873 2016] [:error] [pid 2653] [client 127.0.0.1:59148] PHP Notice:  Object of class Symfony\\Component\\HttpFoundation\\Request could not be converted to int in /home/lpa/atinfo/www/at-info/vendor/symfony/http-foundation/Response.php on line 454, referer: http://at-info/index.php/
[Tue Jun 14 12:30:50.019944 2016] [:error] [pid 2653] [client 127.0.0.1:59148] PHP Fatal error:  Uncaught InvalidArgumentException: The HTTP status code "1" is not valid. in /home/lpa/atinfo/www/at-info/vendor/symfony/http-foundation/Response.php:456\nStack trace:\n#0 /home/lpa/atinfo/www/at-info/vendor/symfony/http-foundation/Response.php(200): Symfony\\Component\\HttpFoundation\\Response->setStatusCode(1)\n#1 /home/lpa/atinfo/www/at-info/src/controllers.php(92): Symfony\\Component\\HttpFoundation\\Response->__construct('<!doctype html>...', Object(Symfony\\Component\\HttpFoundation\\Request))\n#2 [internal function]: {closure}(Object(Symfony\\Component\\HttpKernel\\Exception\\NotFoundHttpException), Object(Symfony\\Component\\HttpFoundation\\Request), 404)\n#3 /home/lpa/atinfo/www/at-info/vendor/silex/silex/src/Silex/ExceptionListenerWrapper.php(53): call_user_func(Object(Closure), Object(Symfony\\Component\\HttpKernel\\Exception\\NotFoundHttpException), Object(Symfony\\Component\\HttpFoundation\\Request), 404)\n#4 [internal function]: Silex\\ExceptionListenerWrapper->__invoke(Object(Symfony\\Component\\HttpKernel\\Event\\GetResponseFo in /home/lpa/atinfo/www/at-info/vendor/symfony/http-foundation/Response.php on line 456, referer: http://at-info/index.php/
[Tue Jun 14 12:30:50.023618 2016] [:error] [pid 2651] [client 127.0.0.1:59142] PHP Notice:  Object of class Symfony\\Component\\HttpFoundation\\Request could not be converted to int in /home/lpa/atinfo/www/at-info/vendor/symfony/http-foundation/Response.php on line 454, referer: http://at-info/index.php/
[Tue Jun 14 12:30:50.023683 2016] [:error] [pid 2651] [client 127.0.0.1:59142] PHP Fatal error:  Uncaught InvalidArgumentException: The HTTP status code "1" is not valid. in /home/lpa/atinfo/www/at-info/vendor/symfony/http-foundation/Response.php:456\nStack trace:\n#0 /home/lpa/atinfo/www/at-info/vendor/symfony/http-foundation/Response.php(200): Symfony\\Component\\HttpFoundation\\Response->setStatusCode(1)\n#1 /home/lpa/atinfo/www/at-info/src/controllers.php(92): Symfony\\Component\\HttpFoundation\\Response->__construct('<!doctype html>...', Object(Symfony\\Component\\HttpFoundation\\Request))\n#2 [internal function]: {closure}(Object(Symfony\\Component\\HttpKernel\\Exception\\NotFoundHttpException), Object(Symfony\\Component\\HttpFoundation\\Request), 404)\n#3 /home/lpa/atinfo/www/at-info/vendor/silex/silex/src/Silex/ExceptionListenerWrapper.php(53): call_user_func(Object(Closure), Object(Symfony\\Component\\HttpKernel\\Exception\\NotFoundHttpException), Object(Symfony\\Component\\HttpFoundation\\Request), 404)\n#4 [internal function]: Silex\\ExceptionListenerWrapper->__invoke(Object(Symfony\\Component\\HttpKernel\\Event\\GetResponseFo in /home/lpa/atinfo/www/at-info/vendor/symfony/http-foundation/Response.php on line 456, referer: http://at-info/index.php/
[Tue Jun 14 12:30:50.024227 2016] [:error] [pid 1183] [client 127.0.0.1:59144] PHP Notice:  Object of class Symfony\\Component\\HttpFoundation\\Request could not be converted to int in /home/lpa/atinfo/www/at-info/vendor/symfony/http-foundation/Response.php on line 454, referer: http://at-info/index.php/
[Tue Jun 14 12:30:50.024313 2016] [:error] [pid 1183] [client 127.0.0.1:59144] PHP Fatal error:  Uncaught InvalidArgumentException: The HTTP status code "1" is not valid. in /home/lpa/atinfo/www/at-info/vendor/symfony/http-foundation/Response.php:456\nStack trace:\n#0 /home/lpa/atinfo/www/at-info/vendor/symfony/http-foundation/Response.php(200): Symfony\\Component\\HttpFoundation\\Response->setStatusCode(1)\n#1 /home/lpa/atinfo/www/at-info/src/controllers.php(92): Symfony\\Component\\HttpFoundation\\Response->__construct('<!doctype html>...', Object(Symfony\\Component\\HttpFoundation\\Request))\n#2 [internal function]: {closure}(Object(Symfony\\Component\\HttpKernel\\Exception\\NotFoundHttpException), Object(Symfony\\Component\\HttpFoundation\\Request), 404)\n#3 /home/lpa/atinfo/www/at-info/vendor/silex/silex/src/Silex/ExceptionListenerWrapper.php(53): call_user_func(Object(Closure), Object(Symfony\\Component\\HttpKernel\\Exception\\NotFoundHttpException), Object(Symfony\\Component\\HttpFoundation\\Request), 404)\n#4 [internal function]: Silex\\ExceptionListenerWrapper->__invoke(Object(Symfony\\Component\\HttpKernel\\Event\\GetResponseFo in /home/lpa/atinfo/www/at-info/vendor/symfony/http-foundation/Response.php on line 456, referer: http://at-info/index.php/
[Tue Jun 14 12:30:50.033902 2016] [:error] [pid 1186] [client 127.0.0.1:59146] PHP Notice:  Object of class Symfony\\Component\\HttpFoundation\\Request could not be converted to int in /home/lpa/atinfo/www/at-info/vendor/symfony/http-foundation/Response.php on line 454, referer: http://at-info/index.php/
[Tue Jun 14 12:30:50.033976 2016] [:error] [pid 1186] [client 127.0.0.1:59146] PHP Fatal error:  Uncaught InvalidArgumentException: The HTTP status code "1" is not valid. in /home/lpa/atinfo/www/at-info/vendor/symfony/http-foundation/Response.php:456\nStack trace:\n#0 /home/lpa/atinfo/www/at-info/vendor/symfony/http-foundation/Response.php(200): Symfony\\Component\\HttpFoundation\\Response->setStatusCode(1)\n#1 /home/lpa/atinfo/www/at-info/src/controllers.php(92): Symfony\\Component\\HttpFoundation\\Response->__construct('<!doctype html>...', Object(Symfony\\Component\\HttpFoundation\\Request))\n#2 [internal function]: {closure}(Object(Symfony\\Component\\HttpKernel\\Exception\\NotFoundHttpException), Object(Symfony\\Component\\HttpFoundation\\Request), 404)\n#3 /home/lpa/atinfo/www/at-info/vendor/silex/silex/src/Silex/ExceptionListenerWrapper.php(53): call_user_func(Object(Closure), Object(Symfony\\Component\\HttpKernel\\Exception\\NotFoundHttpException), Object(Symfony\\Component\\HttpFoundation\\Request), 404)\n#4 [internal function]: Silex\\ExceptionListenerWrapper->__invoke(Object(Symfony\\Component\\HttpKernel\\Event\\GetResponseFo in /home/lpa/atinfo/www/at-info/vendor/symfony/http-foundation/Response.php on line 456, referer: http://at-info/index.php/
[Tue Jun 14 12:30:50.067251 2016] [:error] [pid 2650] [client 127.0.0.1:59150] PHP Notice:  Object of class Symfony\\Component\\HttpFoundation\\Request could not be converted to int in /home/lpa/atinfo/www/at-info/vendor/symfony/http-foundation/Response.php on line 454, referer: http://at-info/index.php/
[Tue Jun 14 12:30:50.067322 2016] [:error] [pid 2650] [client 127.0.0.1:59150] PHP Fatal error:  Uncaught InvalidArgumentException: The HTTP status code "1" is not valid. in /home/lpa/atinfo/www/at-info/vendor/symfony/http-foundation/Response.php:456\nStack trace:\n#0 /home/lpa/atinfo/www/at-info/vendor/symfony/http-foundation/Response.php(200): Symfony\\Component\\HttpFoundation\\Response->setStatusCode(1)\n#1 /home/lpa/atinfo/www/at-info/src/controllers.php(92): Symfony\\Component\\HttpFoundation\\Response->__construct('<!doctype html>...', Object(Symfony\\Component\\HttpFoundation\\Request))\n#2 [internal function]: {closure}(Object(Symfony\\Component\\HttpKernel\\Exception\\NotFoundHttpException), Object(Symfony\\Component\\HttpFoundation\\Request), 404)\n#3 /home/lpa/atinfo/www/at-info/vendor/silex/silex/src/Silex/ExceptionListenerWrapper.php(53): call_user_func(Object(Closure), Object(Symfony\\Component\\HttpKernel\\Exception\\NotFoundHttpException), Object(Symfony\\Component\\HttpFoundation\\Request), 404)\n#4 [internal function]: Silex\\ExceptionListenerWrapper->__invoke(Object(Symfony\\Component\\HttpKernel\\Event\\GetResponseFo in /home/lpa/atinfo/www/at-info/vendor/symfony/http-foundation/Response.php on line 456, referer: http://at-info/index.php/
[Tue Jun 14 12:30:51.571152 2016] [:error] [pid 2652] [client 127.0.0.1:59152] PHP Notice:  Object of class Symfony\\Component\\HttpFoundation\\Request could not be converted to int in /home/lpa/atinfo/www/at-info/vendor/symfony/http-foundation/Response.php on line 454, referer: http://at-info/index.php/
[Tue Jun 14 12:30:51.571239 2016] [:error] [pid 2652] [client 127.0.0.1:59152] PHP Fatal error:  Uncaught InvalidArgumentException: The HTTP status code "1" is not valid. in /home/lpa/atinfo/www/at-info/vendor/symfony/http-foundation/Response.php:456\nStack trace:\n#0 /home/lpa/atinfo/www/at-info/vendor/symfony/http-foundation/Response.php(200): Symfony\\Component\\HttpFoundation\\Response->setStatusCode(1)\n#1 /home/lpa/atinfo/www/at-info/src/controllers.php(92): Symfony\\Component\\HttpFoundation\\Response->__construct('<!doctype html>...', Object(Symfony\\Component\\HttpFoundation\\Request))\n#2 [internal function]: {closure}(Object(Symfony\\Component\\HttpKernel\\Exception\\NotFoundHttpException), Object(Symfony\\Component\\HttpFoundation\\Request), 404)\n#3 /home/lpa/atinfo/www/at-info/vendor/silex/silex/src/Silex/ExceptionListenerWrapper.php(53): call_user_func(Object(Closure), Object(Symfony\\Component\\HttpKernel\\Exception\\NotFoundHttpException), Object(Symfony\\Component\\HttpFoundation\\Request), 404)\n#4 [internal function]: Silex\\ExceptionListenerWrapper->__invoke(Object(Symfony\\Component\\HttpKernel\\Event\\GetResponseFo in /home/lpa/atinfo/www/at-info/vendor/symfony/http-foundation/Response.php on line 456, referer: http://at-info/index.php/
[Tue Jun 14 12:30:51.571299 2016] [:error] [pid 1184] [client 127.0.0.1:59154] PHP Notice:  Object of class Symfony\\Component\\HttpFoundation\\Request could not be converted to int in /home/lpa/atinfo/www/at-info/vendor/symfony/http-foundation/Response.php on line 454, referer: http://at-info/index.php/
[Tue Jun 14 12:30:51.571366 2016] [:error] [pid 1184] [client 127.0.0.1:59154] PHP Fatal error:  Uncaught InvalidArgumentException: The HTTP status code "1" is not valid. in /home/lpa/atinfo/www/at-info/vendor/symfony/http-foundation/Response.php:456\nStack trace:\n#0 /home/lpa/atinfo/www/at-info/vendor/symfony/http-foundation/Response.php(200): Symfony\\Component\\HttpFoundation\\Response->setStatusCode(1)\n#1 /home/lpa/atinfo/www/at-info/src/controllers.php(92): Symfony\\Component\\HttpFoundation\\Response->__construct('<!doctype html>...', Object(Symfony\\Component\\HttpFoundation\\Request))\n#2 [internal function]: {closure}(Object(Symfony\\Component\\HttpKernel\\Exception\\NotFoundHttpException), Object(Symfony\\Component\\HttpFoundation\\Request), 404)\n#3 /home/lpa/atinfo/www/at-info/vendor/silex/silex/src/Silex/ExceptionListenerWrapper.php(53): call_user_func(Object(Closure), Object(Symfony\\Component\\HttpKernel\\Exception\\NotFoundHttpException), Object(Symfony\\Component\\HttpFoundation\\Request), 404)\n#4 [internal function]: Silex\\ExceptionListenerWrapper->__invoke(Object(Symfony\\Component\\HttpKernel\\Event\\GetResponseFo in /home/lpa/atinfo/www/at-info/vendor/symfony/http-foundation/Response.php on line 456, referer: http://at-info/index.php/
[Tue Jun 14 12:30:51.588176 2016] [:error] [pid 1182] [client 127.0.0.1:59156] PHP Notice:  Object of class Symfony\\Component\\HttpFoundation\\Request could not be converted to int in /home/lpa/atinfo/www/at-info/vendor/symfony/http-foundation/Response.php on line 454, referer: http://at-info/index.php/
[Tue Jun 14 12:30:51.592035 2016] [:error] [pid 1185] [client 127.0.0.1:59158] PHP Notice:  Object of class Symfony\\Component\\HttpFoundation\\Request could not be converted to int in /home/lpa/atinfo/www/at-info/vendor/symfony/http-foundation/Response.php on line 454, referer: http://at-info/index.php/
[Tue Jun 14 12:30:51.592274 2016] [:error] [pid 1185] [client 127.0.0.1:59158] PHP Fatal error:  Uncaught InvalidArgumentException: The HTTP status code "1" is not valid. in /home/lpa/atinfo/www/at-info/vendor/symfony/http-foundation/Response.php:456\nStack trace:\n#0 /home/lpa/atinfo/www/at-info/vendor/symfony/http-foundation/Response.php(200): Symfony\\Component\\HttpFoundation\\Response->setStatusCode(1)\n#1 /home/lpa/atinfo/www/at-info/src/controllers.php(92): Symfony\\Component\\HttpFoundation\\Response->__construct('<!doctype html>...', Object(Symfony\\Component\\HttpFoundation\\Request))\n#2 [internal function]: {closure}(Object(Symfony\\Component\\HttpKernel\\Exception\\NotFoundHttpException), Object(Symfony\\Component\\HttpFoundation\\Request), 404)\n#3 /home/lpa/atinfo/www/at-info/vendor/silex/silex/src/Silex/ExceptionListenerWrapper.php(53): call_user_func(Object(Closure), Object(Symfony\\Component\\HttpKernel\\Exception\\NotFoundHttpException), Object(Symfony\\Component\\HttpFoundation\\Request), 404)\n#4 [internal function]: Silex\\ExceptionListenerWrapper->__invoke(Object(Symfony\\Component\\HttpKernel\\Event\\GetResponseFo in /home/lpa/atinfo/www/at-info/vendor/symfony/http-foundation/Response.php on line 456, referer: http://at-info/index.php/
[Tue Jun 14 12:30:51.592961 2016] [:error] [pid 1182] [client 127.0.0.1:59156] PHP Fatal error:  Uncaught InvalidArgumentException: The HTTP status code "1" is not valid. in /home/lpa/atinfo/www/at-info/vendor/symfony/http-foundation/Response.php:456\nStack trace:\n#0 /home/lpa/atinfo/www/at-info/vendor/symfony/http-foundation/Response.php(200): Symfony\\Component\\HttpFoundation\\Response->setStatusCode(1)\n#1 /home/lpa/atinfo/www/at-info/src/controllers.php(92): Symfony\\Component\\HttpFoundation\\Response->__construct('<!doctype html>...', Object(Symfony\\Component\\HttpFoundation\\Request))\n#2 [internal function]: {closure}(Object(Symfony\\Component\\HttpKernel\\Exception\\NotFoundHttpException), Object(Symfony\\Component\\HttpFoundation\\Request), 404)\n#3 /home/lpa/atinfo/www/at-info/vendor/silex/silex/src/Silex/ExceptionListenerWrapper.php(53): call_user_func(Object(Closure), Object(Symfony\\Component\\HttpKernel\\Exception\\NotFoundHttpException), Object(Symfony\\Component\\HttpFoundation\\Request), 404)\n#4 [internal function]: Silex\\ExceptionListenerWrapper->__invoke(Object(Symfony\\Component\\HttpKernel\\Event\\GetResponseFo in /home/lpa/atinfo/www/at-info/vendor/symfony/http-foundation/Response.php on line 456, referer: http://at-info/index.php/
[Tue Jun 14 12:30:51.738639 2016] [:error] [pid 1183] [client 127.0.0.1:59160] PHP Notice:  Object of class Symfony\\Component\\HttpFoundation\\Request could not be converted to int in /home/lpa/atinfo/www/at-info/vendor/symfony/http-foundation/Response.php on line 454, referer: http://at-info/index.php/
[Tue Jun 14 12:30:51.738691 2016] [:error] [pid 1183] [client 127.0.0.1:59160] PHP Fatal error:  Uncaught InvalidArgumentException: The HTTP status code "1" is not valid. in /home/lpa/atinfo/www/at-info/vendor/symfony/http-foundation/Response.php:456\nStack trace:\n#0 /home/lpa/atinfo/www/at-info/vendor/symfony/http-foundation/Response.php(200): Symfony\\Component\\HttpFoundation\\Response->setStatusCode(1)\n#1 /home/lpa/atinfo/www/at-info/src/controllers.php(92): Symfony\\Component\\HttpFoundation\\Response->__construct('<!doctype html>...', Object(Symfony\\Component\\HttpFoundation\\Request))\n#2 [internal function]: {closure}(Object(Symfony\\Component\\HttpKernel\\Exception\\NotFoundHttpException), Object(Symfony\\Component\\HttpFoundation\\Request), 404)\n#3 /home/lpa/atinfo/www/at-info/vendor/silex/silex/src/Silex/ExceptionListenerWrapper.php(53): call_user_func(Object(Closure), Object(Symfony\\Component\\HttpKernel\\Exception\\NotFoundHttpException), Object(Symfony\\Component\\HttpFoundation\\Request), 404)\n#4 [internal function]: Silex\\ExceptionListenerWrapper->__invoke(Object(Symfony\\Component\\HttpKernel\\Event\\GetResponseFo in /home/lpa/atinfo/www/at-info/vendor/symfony/http-foundation/Response.php on line 456, referer: http://at-info/index.php/
[Tue Jun 14 12:30:51.739490 2016] [:error] [pid 2653] [client 127.0.0.1:59162] PHP Notice:  Object of class Symfony\\Component\\HttpFoundation\\Request could not be converted to int in /home/lpa/atinfo/www/at-info/vendor/symfony/http-foundation/Response.php on line 454, referer: http://at-info/index.php/
[Tue Jun 14 12:30:51.739547 2016] [:error] [pid 2653] [client 127.0.0.1:59162] PHP Fatal error:  Uncaught InvalidArgumentException: The HTTP status code "1" is not valid. in /home/lpa/atinfo/www/at-info/vendor/symfony/http-foundation/Response.php:456\nStack trace:\n#0 /home/lpa/atinfo/www/at-info/vendor/symfony/http-foundation/Response.php(200): Symfony\\Component\\HttpFoundation\\Response->setStatusCode(1)\n#1 /home/lpa/atinfo/www/at-info/src/controllers.php(92): Symfony\\Component\\HttpFoundation\\Response->__construct('<!doctype html>...', Object(Symfony\\Component\\HttpFoundation\\Request))\n#2 [internal function]: {closure}(Object(Symfony\\Component\\HttpKernel\\Exception\\NotFoundHttpException), Object(Symfony\\Component\\HttpFoundation\\Request), 404)\n#3 /home/lpa/atinfo/www/at-info/vendor/silex/silex/src/Silex/ExceptionListenerWrapper.php(53): call_user_func(Object(Closure), Object(Symfony\\Component\\HttpKernel\\Exception\\NotFoundHttpException), Object(Symfony\\Component\\HttpFoundation\\Request), 404)\n#4 [internal function]: Silex\\ExceptionListenerWrapper->__invoke(Object(Symfony\\Component\\HttpKernel\\Event\\GetResponseFo in /home/lpa/atinfo/www/at-info/vendor/symfony/http-foundation/Response.php on line 456, referer: http://at-info/index.php/
[Tue Jun 14 12:30:51.746612 2016] [:error] [pid 1186] [client 127.0.0.1:59164] PHP Notice:  Object of class Symfony\\Component\\HttpFoundation\\Request could not be converted to int in /home/lpa/atinfo/www/at-info/vendor/symfony/http-foundation/Response.php on line 454, referer: http://at-info/index.php/
[Tue Jun 14 12:30:51.746668 2016] [:error] [pid 1186] [client 127.0.0.1:59164] PHP Fatal error:  Uncaught InvalidArgumentException: The HTTP status code "1" is not valid. in /home/lpa/atinfo/www/at-info/vendor/symfony/http-foundation/Response.php:456\nStack trace:\n#0 /home/lpa/atinfo/www/at-info/vendor/symfony/http-foundation/Response.php(200): Symfony\\Component\\HttpFoundation\\Response->setStatusCode(1)\n#1 /home/lpa/atinfo/www/at-info/src/controllers.php(92): Symfony\\Component\\HttpFoundation\\Response->__construct('<!doctype html>...', Object(Symfony\\Component\\HttpFoundation\\Request))\n#2 [internal function]: {closure}(Object(Symfony\\Component\\HttpKernel\\Exception\\NotFoundHttpException), Object(Symfony\\Component\\HttpFoundation\\Request), 404)\n#3 /home/lpa/atinfo/www/at-info/vendor/silex/silex/src/Silex/ExceptionListenerWrapper.php(53): call_user_func(Object(Closure), Object(Symfony\\Component\\HttpKernel\\Exception\\NotFoundHttpException), Object(Symfony\\Component\\HttpFoundation\\Request), 404)\n#4 [internal function]: Silex\\ExceptionListenerWrapper->__invoke(Object(Symfony\\Component\\HttpKernel\\Event\\GetResponseFo in /home/lpa/atinfo/www/at-info/vendor/symfony/http-foundation/Response.php on line 456, referer: http://at-info/index.php/
[Tue Jun 14 12:30:51.749153 2016] [:error] [pid 2651] [client 127.0.0.1:59166] PHP Notice:  Object of class Symfony\\Component\\HttpFoundation\\Request could not be converted to int in /home/lpa/atinfo/www/at-info/vendor/symfony/http-foundation/Response.php on line 454, referer: http://at-info/index.php/
[Tue Jun 14 12:30:51.749400 2016] [:error] [pid 2651] [client 127.0.0.1:59166] PHP Fatal error:  Uncaught InvalidArgumentException: The HTTP status code "1" is not valid. in /home/lpa/atinfo/www/at-info/vendor/symfony/http-foundation/Response.php:456\nStack trace:\n#0 /home/lpa/atinfo/www/at-info/vendor/symfony/http-foundation/Response.php(200): Symfony\\Component\\HttpFoundation\\Response->setStatusCode(1)\n#1 /home/lpa/atinfo/www/at-info/src/controllers.php(92): Symfony\\Component\\HttpFoundation\\Response->__construct('<!doctype html>...', Object(Symfony\\Component\\HttpFoundation\\Request))\n#2 [internal function]: {closure}(Object(Symfony\\Component\\HttpKernel\\Exception\\NotFoundHttpException), Object(Symfony\\Component\\HttpFoundation\\Request), 404)\n#3 /home/lpa/atinfo/www/at-info/vendor/silex/silex/src/Silex/ExceptionListenerWrapper.php(53): call_user_func(Object(Closure), Object(Symfony\\Component\\HttpKernel\\Exception\\NotFoundHttpException), Object(Symfony\\Component\\HttpFoundation\\Request), 404)\n#4 [internal function]: Silex\\ExceptionListenerWrapper->__invoke(Object(Symfony\\Component\\HttpKernel\\Event\\GetResponseFo in /home/lpa/atinfo/www/at-info/vendor/symfony/http-foundation/Response.php on line 456, referer: http://at-info/index.php/
[Tue Jun 14 12:30:51.778444 2016] [:error] [pid 2650] [client 127.0.0.1:59168] PHP Notice:  Object of class Symfony\\Component\\HttpFoundation\\Request could not be converted to int in /home/lpa/atinfo/www/at-info/vendor/symfony/http-foundation/Response.php on line 454, referer: http://at-info/index.php/
[Tue Jun 14 12:30:51.778499 2016] [:error] [pid 2650] [client 127.0.0.1:59168] PHP Fatal error:  Uncaught InvalidArgumentException: The HTTP status code "1" is not valid. in /home/lpa/atinfo/www/at-info/vendor/symfony/http-foundation/Response.php:456\nStack trace:\n#0 /home/lpa/atinfo/www/at-info/vendor/symfony/http-foundation/Response.php(200): Symfony\\Component\\HttpFoundation\\Response->setStatusCode(1)\n#1 /home/lpa/atinfo/www/at-info/src/controllers.php(92): Symfony\\Component\\HttpFoundation\\Response->__construct('<!doctype html>...', Object(Symfony\\Component\\HttpFoundation\\Request))\n#2 [internal function]: {closure}(Object(Symfony\\Component\\HttpKernel\\Exception\\NotFoundHttpException), Object(Symfony\\Component\\HttpFoundation\\Request), 404)\n#3 /home/lpa/atinfo/www/at-info/vendor/silex/silex/src/Silex/ExceptionListenerWrapper.php(53): call_user_func(Object(Closure), Object(Symfony\\Component\\HttpKernel\\Exception\\NotFoundHttpException), Object(Symfony\\Component\\HttpFoundation\\Request), 404)\n#4 [internal function]: Silex\\ExceptionListenerWrapper->__invoke(Object(Symfony\\Component\\HttpKernel\\Event\\GetResponseFo in /home/lpa/atinfo/www/at-info/vendor/symfony/http-foundation/Response.php on line 456, referer: http://at-info/index.php/
[Sat Jun 18 12:19:51.802187 2016] [:error] [pid 2853] [client 127.0.0.1:53946] PHP Warning:  Missing argument 2 for Symfony\\Component\\HttpFoundation\\Session\\Flash\\FlashBag::add(), called in /home/lpa/atinfo/www/at-info/src/controllers.php on line 85 and defined in /home/lpa/atinfo/www/at-info/vendor/symfony/http-foundation/Session/Flash/FlashBag.php on line 71
[Sat Jun 18 12:19:51.804032 2016] [:error] [pid 2853] [client 127.0.0.1:53946] PHP Notice:  Undefined variable: message in /home/lpa/atinfo/www/at-info/vendor/symfony/http-foundation/Session/Flash/FlashBag.php on line 73
[Sat Jun 18 12:19:52.141002 2016] [:error] [pid 2853] [client 127.0.0.1:53946] PHP Warning:  Missing argument 2 for Symfony\\Component\\HttpFoundation\\Session\\Flash\\FlashBag::add(), called in /home/lpa/atinfo/www/at-info/src/controllers.php on line 85 and defined in /home/lpa/atinfo/www/at-info/vendor/symfony/http-foundation/Session/Flash/FlashBag.php on line 71, referer: http://at-info/index.php/
[Sat Jun 18 12:19:52.141024 2016] [:error] [pid 2853] [client 127.0.0.1:53946] PHP Notice:  Undefined variable: message in /home/lpa/atinfo/www/at-info/vendor/symfony/http-foundation/Session/Flash/FlashBag.php on line 73, referer: http://at-info/index.php/
[Sat Jun 18 12:19:52.144270 2016] [:error] [pid 2853] [client 127.0.0.1:53946] PHP Warning:  Missing argument 2 for Symfony\\Component\\HttpFoundation\\Session\\Flash\\FlashBag::add(), called in /home/lpa/atinfo/www/at-info/src/controllers.php on line 85 and defined in /home/lpa/atinfo/www/at-info/vendor/symfony/http-foundation/Session/Flash/FlashBag.php on line 71, referer: http://at-info/index.php/
[Sat Jun 18 12:19:52.144301 2016] [:error] [pid 2853] [client 127.0.0.1:53946] PHP Notice:  Undefined variable: message in /home/lpa/atinfo/www/at-info/vendor/symfony/http-foundation/Session/Flash/FlashBag.php on line 73, referer: http://at-info/index.php/
[Sat Jun 18 12:19:52.147581 2016] [:error] [pid 2853] [client 127.0.0.1:53946] PHP Warning:  Missing argument 2 for Symfony\\Component\\HttpFoundation\\Session\\Flash\\FlashBag::add(), called in /home/lpa/atinfo/www/at-info/src/controllers.php on line 85 and defined in /home/lpa/atinfo/www/at-info/vendor/symfony/http-foundation/Session/Flash/FlashBag.php on line 71, referer: http://at-info/index.php/
[Sat Jun 18 12:19:52.147598 2016] [:error] [pid 2853] [client 127.0.0.1:53946] PHP Notice:  Undefined variable: message in /home/lpa/atinfo/www/at-info/vendor/symfony/http-foundation/Session/Flash/FlashBag.php on line 73, referer: http://at-info/index.php/
[Sat Jun 18 12:19:52.153823 2016] [:error] [pid 2853] [client 127.0.0.1:53946] PHP Warning:  Missing argument 2 for Symfony\\Component\\HttpFoundation\\Session\\Flash\\FlashBag::add(), called in /home/lpa/atinfo/www/at-info/src/controllers.php on line 85 and defined in /home/lpa/atinfo/www/at-info/vendor/symfony/http-foundation/Session/Flash/FlashBag.php on line 71, referer: http://at-info/index.php/
[Sat Jun 18 12:19:52.153842 2016] [:error] [pid 2853] [client 127.0.0.1:53946] PHP Notice:  Undefined variable: message in /home/lpa/atinfo/www/at-info/vendor/symfony/http-foundation/Session/Flash/FlashBag.php on line 73, referer: http://at-info/index.php/
[Sat Jun 18 12:19:52.157603 2016] [:error] [pid 1227] [client 127.0.0.1:53948] PHP Warning:  Missing argument 2 for Symfony\\Component\\HttpFoundation\\Session\\Flash\\FlashBag::add(), called in /home/lpa/atinfo/www/at-info/src/controllers.php on line 85 and defined in /home/lpa/atinfo/www/at-info/vendor/symfony/http-foundation/Session/Flash/FlashBag.php on line 71, referer: http://at-info/index.php/
[Sat Jun 18 12:19:52.157627 2016] [:error] [pid 1227] [client 127.0.0.1:53948] PHP Notice:  Undefined variable: message in /home/lpa/atinfo/www/at-info/vendor/symfony/http-foundation/Session/Flash/FlashBag.php on line 73, referer: http://at-info/index.php/
[Sat Jun 18 12:25:21.791240 2016] [:error] [pid 1225] [client 127.0.0.1:54022] PHP Warning:  Missing argument 2 for Symfony\\Component\\HttpFoundation\\Session\\Flash\\FlashBag::add(), called in /home/lpa/atinfo/www/at-info/src/controllers.php on line 85 and defined in /home/lpa/atinfo/www/at-info/vendor/symfony/http-foundation/Session/Flash/FlashBag.php on line 71
[Sat Jun 18 12:25:21.791270 2016] [:error] [pid 1225] [client 127.0.0.1:54022] PHP Notice:  Undefined variable: message in /home/lpa/atinfo/www/at-info/vendor/symfony/http-foundation/Session/Flash/FlashBag.php on line 73
[Sat Jun 18 12:26:34.764502 2016] [:error] [pid 1224] [client 127.0.0.1:54046] PHP Warning:  Missing argument 2 for Symfony\\Component\\HttpFoundation\\Session\\Flash\\FlashBag::add(), called in /home/lpa/atinfo/www/at-info/src/controllers.php on line 85 and defined in /home/lpa/atinfo/www/at-info/vendor/symfony/http-foundation/Session/Flash/FlashBag.php on line 71
[Sat Jun 18 12:26:34.764529 2016] [:error] [pid 1224] [client 127.0.0.1:54046] PHP Notice:  Undefined variable: message in /home/lpa/atinfo/www/at-info/vendor/symfony/http-foundation/Session/Flash/FlashBag.php on line 73
[Sat Jun 18 12:29:44.994684 2016] [:error] [pid 1227] [client 127.0.0.1:54068] PHP Warning:  Missing argument 2 for Symfony\\Component\\HttpFoundation\\Session\\Flash\\FlashBag::add(), called in /home/lpa/atinfo/www/at-info/src/controllers.php on line 85 and defined in /home/lpa/atinfo/www/at-info/vendor/symfony/http-foundation/Session/Flash/FlashBag.php on line 71
[Sat Jun 18 12:29:44.994719 2016] [:error] [pid 1227] [client 127.0.0.1:54068] PHP Notice:  Undefined variable: message in /home/lpa/atinfo/www/at-info/vendor/symfony/http-foundation/Session/Flash/FlashBag.php on line 73
[Sat Jun 18 12:53:01.901501 2016] [:error] [pid 3592] [client 127.0.0.1:54472] PHP Parse error:  syntax error, unexpected '}' in /home/lpa/atinfo/www/at-info/src/controllers.php on line 95
[Sat Jun 18 13:12:07.386020 2016] [:error] [pid 1227] [client 127.0.0.1:55484] PHP Parse error:  syntax error, unexpected ',' in /home/lpa/atinfo/www/at-info/src/controllers.php on line 29
[Tue Jun 21 16:45:04.485148 2016] [:error] [pid 3592] [client 127.0.0.1:41708] PHP Parse error:  syntax error, unexpected ',', expecting ']' in /home/lpa/atinfo/www/at-info/src/controllers.php on line 101
[Tue Jun 21 16:45:09.411510 2016] [:error] [pid 2799] [client 127.0.0.1:41710] PHP Parse error:  syntax error, unexpected ',', expecting ']' in /home/lpa/atinfo/www/at-info/src/controllers.php on line 101
[Tue Jun 21 16:45:16.093653 2016] [:error] [pid 1223] [client 127.0.0.1:41712] PHP Parse error:  syntax error, unexpected ',', expecting ']' in /home/lpa/atinfo/www/at-info/src/controllers.php on line 101
